Workbook

Sheet Index A
A1: Tampa Bay Buccaneers | B1: Buccaneers | D1: MIA | E1: Dolphins
A2: Washington Commanders | B2: Commanders | D2: SFO | E2: 49ers
A3: Seattle Seahawks | B3: Seahawks | D3: DET | E3: Lions
A4: Carolina Panthers | B4: Panthers | D4: DAL | E4: Cowboys
A5: Kansas City Chiefs | B5: Chiefs | D5: KAN | E5: Chiefs
A6: Tennessee Titans | B6: Titans | D6: LAR | E6: Rams
A7: New York Jets | B7: Jets | D7: BUF | E7: Bills
A8: Arizona Cardinals | B8: Cardinals | D8: TAM | E8: Buccaneers
A9: San Francisco 49ers | B9: 49ers | D9: HOU | E9: Texans
A10: Houston Texans | B10: Texans | D10: GNB | E10: Packers
A11: Jacksonville Jaguars | B11: Jaguars | D11: PHI | E11: Eagles
A12: Buffalo Bills | B12: Bills | D12: WAS | E12: Commanders
... A32: Denver Broncos | B32: Broncos | D32: NYG | E32: Giants

Sheet Paste
A1: FUTURES | B1: Consensus | H1: https://www.actionnetwork.com/nfl/futures/win-totals-odds
B2: o8.5 | C2: N/A | D2: o8.5+150 | E2: o9.5+215 | F2: o7.5-132 | G2: o7.5-136 | H2: =A3 -> Tampa Bay Buccaneers | I2: =_xlfn.NUMBERVALUE(RIGHT(B2,LEN(B2)-1)) -> 8.5 | J2: Over | K2: =J2 -> Over | L2: =J3 -> 150 | M2: =INDEX('Index A'!$B$1:$B$32,MATCH($H2,'Index A'!$A$1:$A$32,0)) -> Buccaneers
A3: Tampa Bay Buccaneers | B3: 150 | C3: N/A | D3: u8.5-175 | E3: u9.5-275 | F3: u7.5+104 | G3: u7.5+112 | H3: =H2 -> Tampa Bay Buccaneers | I3: =I2 -> 8.5 | J3: =B3 -> 150 | K3: =K2 -> Over | L3: =L2 -> 150 | M3: =INDEX('Index A'!$B$1:$B$32,MATCH($H3,'Index A'!$A$1:$A$32,0)) -> Buccaneers
B4: u8.5 | H4: =H3 -> Tampa Bay Buccaneers | I4: =_xlfn.NUMBERVALUE(RIGHT(B4,LEN(B4)-1)) -> 8.5 | J4: Under | K4: =J4 -> Under | L4: =J5 -> -175 | M4: =INDEX('Index A'!$B$1:$B$32,MATCH($H4,'Index A'!$A$1:$A$32,0)) -> Buccaneers
B5: -175 | H5: =H4 -> Tampa Bay Buccaneers | I5: =I4 -> 8.5 | J5: =B5 -> -175 | K5: =K4 -> Under | L5: =L4 -> -175 | M5: =INDEX('Index A'!$B$1:$B$32,MATCH($H5,'Index A'!$A$1:$A$32,0)) -> Buccaneers
B6: o6.5 | C6: N/A | D6: o6.5-115 | E6: o6.5-130 | F6: o6.5-120 | G6: o6.5-121 | H6: =A7 -> Washington Commanders | I6: =_xlfn.NUMBERVALUE(RIGHT(B6,LEN(B6)-1)) -> 6.5 | J6: Over | K6: =J6 -> Over | L6: =J7 -> -130 | M6: =INDEX('Index A'!$B$1:$B$32,MATCH($H6,'Index A'!$A$1:$A$32,0)) -> Commanders
A7: Washington Commanders | B7: -130 | C7: N/A | D7: u6.5-105 | E7: u6.5+110 | F7: u6.5-102 | G7: u6.5+100 | H7: =H6 -> Washington Commanders | I7: =I6 -> 6.5 | J7: =B7 -> -130 | K7: =K6 -> Over | L7: =L6 -> -130 | M7: =INDEX('Index A'!$B$1:$B$32,MATCH($H7,'Index A'!$A$1:$A$32,0)) -> Commanders
B8: u6.5 | H8: =H7 -> Washington Commanders | I8: =_xlfn.NUMBERVALUE(RIGHT(B8,LEN(B8)-1)) -> 6.5 | J8: Under | K8: =J8 -> Under | L8: =J9 -> 110 | M8: =INDEX('Index A'!$B$1:$B$32,MATCH($H8,'Index A'!$A$1:$A$32,0)) -> Commanders
B9: 110 | H9: =H8 -> Washington Commanders | I9: =I8 -> 6.5 | J9: =B9 -> 110 | K9: =K8 -> Under | L9: =L8 -> 110 | M9: =INDEX('Index A'!$B$1:$B$32,MATCH($H9,'Index A'!$A$1:$A$32,0)) -> Commanders
B10: o7.5 | C10: N/A | D10: o8-130 | E10: o7.5-150 | F10: o7.5-158 | G10: o7.5-152 | H10: =A11 -> Seattle Seahawks | I10: =_xlfn.NUMBERVALUE(RIGHT(B10,LEN(B10)-1)) -> 7.5 | J10: Over | K10: =J10 -> Over | L10: =J11 -> -158 | M10: =INDEX('Index A'!$B$1:$B$32,MATCH($H10,'Index A'!$A$1:$A$32,0)) -> Seahawks
A11: Seattle Seahawks | B11: -158 | C11: N/A | D11: u8+110 | E11: u7.5+130 | F11: u7.5+128 | G11: u7.5+125 | H11: =H10 -> Seattle Seahawks | I11: =I10 -> 7.5 | J11: =B11 -> -158 | K11: =K10 -> Over | L11: =L10 -> -158 | M11: =INDEX('Index A'!$B$1:$B$32,MATCH($H11,'Index A'!$A$1:$A$32,0)) -> Seahawks
B12: u7.5 | H12: =H11 -> Seattle Seahawks | I12: =_xlfn.NUMBERVALUE(RIGHT(B12,LEN(B12)-1)) -> 7.5 | J12: Under | K12: =J12 -> Under | L12: =J13 -> 130 | M12: =INDEX('Index A'!$B$1:$B$32,MATCH($H12,'Index A'!$A$1:$A$32,0)) -> Seahawks
B13: 130 | H13: =H12 -> Seattle Seahawks | I13: =I12 -> 7.5 | J13: =B13 -> 130 | K13: =K12 -> Under | L13: =L12 -> 130 | M13: =INDEX('Index A'!$B$1:$B$32,MATCH($H13,'Index A'!$A$1:$A$32,0)) -> Seahawks
B14: o5 | C14: N/A | D14: o5.5-115 | E14: o4.5-225 | F14: o5.5-124 | G14: o5.5-118 | H14: =A15 -> Carolina Panthers | I14: =_xlfn.NUMBERVALUE(RIGHT(B14,LEN(B14)-1)) -> 5 | J14: Over | K14: =J14 -> Over | L14: =J15 -> -159 | M14: =INDEX('Index A'!$B$1:$B$32,MATCH($H14,'Index A'!$A$1:$A$32,0)) -> Panthers
A15: Carolina Panthers | B15: -159 | C15: N/A | D15: u5.5-105 | E15: u4.5+180 | F15: u5.5+102 | G15: u5.5-104 | H15: =H14 -> Carolina Panthers | I15: =I14 -> 5 | J15: =B15 -> -159 | K15: =K14 -> Over | L15: =L14 -> -159 | M15: =INDEX('Index A'!$B$1:$B$32,MATCH($H15,'Index A'!$A$1:$A$32,0)) -> Panthers
B16: u5 | H16: =H15 -> Carolina Panthers | I16: =_xlfn.NUMBERVALUE(RIGHT(B16,LEN(B16)-1)) -> 5 | J16: Under | K16: =J16 -> Under | L16: =J17 -> 137 | M16: =INDEX('Index A'!$B$1:$B$32,MATCH($H16,'Index A'!$A$1:$A$32,0)) -> Panthers
B17: 137 | H17: =H16 -> Carolina Panthers | I17: =I16 -> 5 | J17: =B17 -> 137 | K17: =K16 -> Under | L17: =L16 -> 137 | M17: =INDEX('Index A'!$B$1:$B$32,MATCH($H17,'Index A'!$A$1:$A$32,0)) -> Panthers
B18: o11.5 | C18: N/A | D18: o11.5-110 | E18: o10.5-245 | F18: o11.5-112 | G18: o11.5-118 | H18: =A19 -> Kansas City Chiefs | I18: =_xlfn.NUMBERVALUE(RIGHT(B18,LEN(B18)-1)) -> 11.5 | J18: Over | K18: =J18 -> Over | L18: =J19 -> -110 | M18: =INDEX('Index A'!$B$1:$B$32,MATCH($H18,'Index A'!$A$1:$A$32,0)) -> Chiefs
A19: Kansas City Chiefs | B19: -110 | C19: N/A | D19: u11.5-110 | E19: u10.5+190 | F19: u11.5-108 | G19: u11.5-104 | H19: =H18 -> Kansas City Chiefs | I19: =I18 -> 11.5 | J19: =B19 -> -110 | K19: =K18 -> Over | L19: =L18 -> -110 | M19: =INDEX('Index A'!$B$1:$B$32,MATCH($H19,'Index A'!$A$1:$A$32,0)) -> Chiefs
B20: u11.5 | H20: =H19 -> Kansas City Chiefs | I20: =_xlfn.NUMBERVALUE(RIGHT(B20,LEN(B20)-1)) -> 11.5 | J20: Under | K20: =J20 -> Under | L20: =J21 -> -105 | M20: =INDEX('Index A'!$B$1:$B$32,MATCH($H20,'Index A'!$A$1:$A$32,0)) -> Chiefs
B21: -105 | H21: =H20 -> Kansas City Chiefs | I21: =I20 -> 11.5 | J21: =B21 -> -105 | K21: =K20 -> Under | L21: =L20 -> -105 | M21: =INDEX('Index A'!$B$1:$B$32,MATCH($H21,'Index A'!$A$1:$A$32,0)) -> Chiefs
B22: o6.5 | C22: N/A | D22: o6.5+105 | E22: o4.5-290 | F22: o6.5+104 | G22: o6.5+110 | H22: =A23 -> Tennessee Titans | I22: =_xlfn.NUMBERVALUE(RIGHT(B22,LEN(B22)-1)) -> 6.5 | J22: Over | K22: =J22 -> Over | L22: =J23 -> 104 | M22: =INDEX('Index A'!$B$1:$B$32,MATCH($H22,'Index A'!$A$1:$A$32,0)) -> Titans
A23: Tennessee Titans | B23: 104 | C23: N/A | D23: u6.5-125 | E23: u4.5+220 | F23: u6.5-128 | G23: u6.5-134 | H23: =H22 -> Tennessee Titans | I23: =I22 -> 6.5 | J23: =B23 -> 104 | K23: =K22 -> Over | L23: =L22 -> 104 | M23: =INDEX('Index A'!$B$1:$B$32,MATCH($H23,'Index A'!$A$1:$A$32,0)) -> Titans
B24: u6.5 | H24: =H23 -> Tennessee Titans | I24: =_xlfn.NUMBERVALUE(RIGHT(B24,LEN(B24)-1)) -> 6.5 | J24: Under | K24: =J24 -> Under | L24: =J25 -> -125 | M24: =INDEX('Index A'!$B$1:$B$32,MATCH($H24,'Index A'!$A$1:$A$32,0)) -> Titans
B25: -125 | H25: =H24 -> Tennessee Titans | I25: =I24 -> 6.5 | J25: =B25 -> -125 | K25: =K24 -> Under | L25: =L24 -> -125 | M25: =INDEX('Index A'!$B$1:$B$32,MATCH($H25,'Index A'!$A$1:$A$32,0)) -> Titans
B26: o9.5 | C26: N/A | D26: o10+100 | E26: o9.5-155 | F26: o9.5-162 | G26: o9.5-155 | H26: =A27 -> New York Jets | I26: =_xlfn.NUMBERVALUE(RIGHT(B26,LEN(B26)-1)) -> 9.5 | J26: Over | K26: =J26 -> Over | L26: =J27 -> -162 | M26: =INDEX('Index A'!$B$1:$B$32,MATCH($H26,'Index A'!$A$1:$A$32,0)) -> Jets
A27: New York Jets | B27: -162 | C27: N/A | D27: u10-120 | E27: u9.5+130 | F27: u9.5+132 | G27: u9.5+127 | H27: =H26 -> New York Jets | I27: =I26 -> 9.5 | J27: =B27 -> -162 | K27: =K26 -> Over | L27: =L26 -> -162 | M27: =INDEX('Index A'!$B$1:$B$32,MATCH($H27,'Index A'!$A$1:$A$32,0)) -> Jets
B28: u9.5 | H28: =H27 -> New York Jets | I28: =_xlfn.NUMBERVALUE(RIGHT(B28,LEN(B28)-1)) -> 9.5 | J28: Under | K28: =J28 -> Under | L28: =J29 -> 132 | M28: =INDEX('Index A'!$B$1:$B$32,MATCH($H28,'Index A'!$A$1:$A$32,0)) -> Jets
B29: 132 | H29: =H28 -> New York Jets | I29: =I28 -> 9.5 | J29: =B29 -> 132 | K29: =K28 -> Under | L29: =L28 -> 132 | M29: =INDEX('Index A'!$B$1:$B$32,MATCH($H29,'Index A'!$A$1:$A$32,0)) -> Jets
B30: o7 | C30: N/A | D30: o7-125 | E30: o6.5-150 | F30: o7.5+124 | G30: o6.5-177 | H30: =A31 -> Arizona Cardinals | I30: =_xlfn.NUMBERVALUE(RIGHT(B30,LEN(B30)-1)) -> 7 | J30: Over | K30: =J30 -> Over | L30: =J31 -> -125 | M30: =INDEX('Index A'!$B$1:$B$32,MATCH($H30,'Index A'!$A$1:$A$32,0)) -> Cardinals
A31: Arizona Cardinals | B31: -125 | C31: N/A | D31: u7+105 | E31: u6.5+125 | F31: u7.5-152 | G31: u6.5+144 | H31: =H30 -> Arizona Cardinals | I31: =I30 -> 7 | J31: =B31 -> -125 | K31: =K30 -> Over | L31: =L30 -> -125 | M31: =INDEX('Index A'!$B$1:$B$32,MATCH($H31,'Index A'!$A$1:$A$32,0)) -> Cardinals
B32: u7 | H32: =H31 -> Arizona Cardinals | I32: =_xlfn.NUMBERVALUE(RIGHT(B32,LEN(B32)-1)) -> 7 | J32: Under | K32: =J32 -> Under | L32: =J33 -> 105 | M32: =INDEX('Index A'!$B$1:$B$32,MATCH($H32,'Index A'!$A$1:$A$32,0)) -> Cardinals
B33: 105 | H33: =H32 -> Arizona Cardinals | I33: =I32 -> 7 | J33: =B33 -> 105 | K33: =K32 -> Under | L33: =L32 -> 105 | M33: =INDEX('Index A'!$B$1:$B$32,MATCH($H33,'Index A'!$A$1:$A$32,0)) -> Cardinals
B34: o11.5 | C34: N/A | D34: o11-135 | E34: o11.5+125 | F34: o11.5+116 | G34: o11.5+118 | H34: =A35 -> San Francisco 49ers | I34: =_xlfn.NUMBERVALUE(RIGHT(B34,LEN(B34)-1)) -> 11.5 | J34: Over | K34: =J34 -> Over | L34: =J35 -> 125 | M34: =INDEX('Index A'!$B$1:$B$32,MATCH($H34,'Index A'!$A$1:$A$32,0)) -> 49ers
A35: San Francisco 49ers | B35: 125 | C35: N/A | D35: u11+115 | E35: u11.5-145 | F35: u11.5-142 | G35: u11.5-143 | H35: =H34 -> San Francisco 49ers | I35: =I34 -> 11.5 | J35: =B35 -> 125 | K35: =K34 -> Over | L35: =L34 -> 125 | M35: =INDEX('Index A'!$B$1:$B$32,MATCH($H35,'Index A'!$A$1:$A$32,0)) -> 49ers
B36: u11.5 | H36: =H35 -> San Francisco 49ers | I36: =_xlfn.NUMBERVALUE(RIGHT(B36,LEN(B36)-1)) -> 11.5 | J36: Under | K36: =J36 -> Under | L36: =J37 -> -145 | M36: =INDEX('Index A'!$B$1:$B$32,MATCH($H36,'Index A'!$A$1:$A$32,0)) -> 49ers
B37: -145 | H37: =H36 -> San Francisco 49ers | I37: =I36 -> 11.5 | J37: =B37 -> -145 | K37: =K36 -> Under | L37: =L36 -> -145 | M37: =INDEX('Index A'!$B$1:$B$32,MATCH($H37,'Index A'!$A$1:$A$32,0)) -> 49ers
B38: o9.5 | C38: N/A | D38: o9.5-140 | E38: o9.5-140 | F38: o9.5-158 | G38: o9.5-152 | H38: =A39 -> Houston Texans | I38: =_xlfn.NUMBERVALUE(RIGHT(B38,LEN(B38)-1)) -> 9.5 | J38: Over | K38: =J38 -> Over | L38: =J39 -> -140 | M38: =INDEX('Index A'!$B$1:$B$32,MATCH($H38,'Index A'!$A$1:$A$32,0)) -> Texans
A39: Houston Texans | B39: -140 | C39: N/A | D39: u9.5+120 | E39: u9.5+120 | F39: u9.5+128 | G39: u9.5+125 | H39: =H38 -> Houston Texans | I39: =I38 -> 9.5 | J39: =B39 -> -140 | K39: =K38 -> Over | L39: =L38 -> -140 | M39: =INDEX('Index A'!$B$1:$B$32,MATCH($H39,'Index A'!$A$1:$A$32,0)) -> Texans
B40: u9.5 | H40: =H39 -> Houston Texans | I40: =_xlfn.NUMBERVALUE(RIGHT(B40,LEN(B40)-1)) -> 9.5 | J40: Under | K40: =J40 -> Under | L40: =J41 -> 120 | M40: =INDEX('Index A'!$B$1:$B$32,MATCH($H40,'Index A'!$A$1:$A$32,0)) -> Texans
...

Sheet Auction
A1: Team | B1: Division | C1: Vegas | D1: Athletic | E1: Gut Feeling | F1: New Score | G1: Avg | H1: VBD | I1: Avg I | J1: VBD I | K1: Exp. | L1: Exp. I | M1: Tier | N1: Drafted by | O1: Paid | P1: Team | Q1: Value | R1: Value % | U1: Initial | W1: Inflation Adj.
A2: Ravens | B2: AFC North | C2: 11.5 | D2: 10.9 | E2: 0 | F2: =IFERROR(AVERAGE(D2,C2)+E2,"") -> 11.2 | G2: =F2 -> 11.2 | H2: =G2-MIN($G$2:$G$33) -> 6.75 | I2: =IF(N2<>"","-",G2) -> - | J2: =IF(N2<>"","-",G2-MIN($I$2:$I$33)) -> - | K2: =IFERROR(H2*$V$7,"") -> 21.310182 | L2: =IFERROR(IF(N2<>"","-",J2*$X$7),"") -> - | M2: 1 | N2: Sean | O2: 22 | P2: Ravens | Q2: =IF(N2<>"",K2-O2,"") -> -0.68981847 | R2: =IFERROR(IF(N2<>"",O2/K2-1,""),"") -> 0.03237037 | U2: Budget | V2: 50 | W2: Avg. Left | X2: =AVERAGE($Z$14:$Z$21) -> 0.375
A3: Seahawks | B3: NFC West | C3: 10.5 | D3: 10.8 | E3: 0.5 | F3: =IFERROR(AVERAGE(D3,C3)+E3,"") -> 11.15 | G3: =F3 -> 11.15 | H3: =G3-MIN($G$2:$G$33) -> 6.7 | I3: =IF(N3<>"","-",G3) -> - | J3: =IF(N3<>"","-",G3-MIN($I$2:$I$33)) -> - | K3: =IFERROR(H3*$V$7,"") -> 21.152328 | L3: =IFERROR(IF(N3<>"","-",J3*$X$7),"") -> - | M3: 1 | N3: Evan | O3: 19 | P3: Seahawks | Q3: =IF(N3<>"",K3-O3,"") -> 2.1523283 | R3: =IFERROR(IF(N3<>"",O3/K3-1,""),"") -> -0.10175373 | U3: Players | V3: 8 | W3: Players | X3: =V3 -> 8
A4: Lions | B4: NFC North | C4: 10.5 | D4: 10.2 | E4: 0.5 | F4: =IFERROR(AVERAGE(D4,C4)+E4,"") -> 10.85 | G4: =F4 -> 10.85 | H4: =G4-MIN($G$2:$G$33) -> 6.4 | I4: =IF(N4<>"","-",G4) -> - | J4: =IF(N4<>"","-",G4-MIN($I$2:$I$33)) -> - | K4: =IFERROR(H4*$V$7,"") -> 20.205209 | L4: =IFERROR(IF(N4<>"","-",J4*$X$7),"") -> - | M4: 2 | N4: Leo | O4: 23 | P4: Lions | Q4: =IF(N4<>"",K4-O4,"") -> -2.7947908 | R4: =IFERROR(IF(N4<>"",O4/K4-1,""),"") -> 0.13832031 | U4: Teams | V4: 4 | W4: Teams | X4: =AVERAGE($X$14:$X$21) -> 0
A5: Bills | B5: AFC East | C5: 10.5 | D5: 10.7 | E5: 0 | F5: =IFERROR(AVERAGE(D5,C5)+E5,"") -> 10.6 | G5: =F5 -> 10.6 | H5: =G5-MIN($G$2:$G$33) -> 6.15 | I5: =IF(N5<>"","-",G5) -> - | J5: =IF(N5<>"","-",G5-MIN($I$2:$I$33)) -> - | K5: =IFERROR(H5*$V$7,"") -> 19.415943 | L5: =IFERROR(IF(N5<>"","-",J5*$X$7),"") -> - | M5: 2 | N5: Barry | O5: 23 | P5: Bills | Q5: =IF(N5<>"",K5-O5,"") -> -3.5840568 | R5: =IFERROR(IF(N5<>"",O5/K5-1,""),"") -> 0.1845935 | U5: Total | V5: =V3*V2 -> 400 | W5: Total | X5: =SUM($Z$14:$Z$21) -> 3
A6: Rams | B6: NFC West | C6: 10.5 | D6: 11.6 | E6: -0.5 | F6: =IFERROR(AVERAGE(D6,C6)+E6,"") -> 10.55 | G6: =F6 -> 10.55 | H6: =G6-MIN($G$2:$G$33) -> 6.1 | I6: =IF(N6<>"","-",G6) -> - | J6: =IF(N6<>"","-",G6-MIN($I$2:$I$33)) -> - | K6: =IFERROR(H6*$V$7,"") -> 19.25809 | L6: =IFERROR(IF(N6<>"","-",J6*$X$7),"") -> - | M6: 2 | N6: Leo | O6: 24 | P6: Rams | Q6: =IF(N6<>"",K6-O6,"") -> -4.74191 | R6: =IFERROR(IF(N6<>"",O6/K6-1,""),"") -> 0.24622951 | U6: Baseline | V6: =MIN($G$2:$G$33) -> 4.45 | W6: Baseline | X6: =_xlfn.MINIFS($G$2:$G$33,$N$2:$N$33,"=""") -> 0
A7: Bears | B7: NFC North | C7: 9.5 | D7: 9.6 | E7: 0.5 | F7: =IFERROR(AVERAGE(D7,C7)+E7,"") -> 10.05 | G7: =F7 -> 10.05 | H7: =G7-MIN($G$2:$G$33) -> 5.6 | I7: =IF(N7<>"","-",G7) -> - | J7: =IF(N7<>"","-",G7-MIN($I$2:$I$33)) -> - | K7: =IFERROR(H7*$V$7,"") -> 17.679558 | L7: =IFERROR(IF(N7<>"","-",J7*$X$7),"") -> - | M7: 3 | N7: John | O7: 13 | P7: Bears | Q7: =IF(N7<>"",K7-O7,"") -> 4.679558 | R7: =IFERROR(IF(N7<>"",O7/K7-1,""),"") -> -0.2646875 | U7: Multi | V7: =V5/V8 -> 3.1570639 | W7: Multi | X7: =X5/X8 -> #DIV/0!
A8: Eagles | B8: NFC East | C8: 10.5 | D8: 10.4 | E8: -0.5 | F8: =IFERROR(AVERAGE(D8,C8)+E8,"") -> 9.95 | G8: =F8 -> 9.95 | H8: =G8-MIN($G$2:$G$33) -> 5.5 | I8: =IF(N8<>"","-",G8) -> - | J8: =IF(N8<>"","-",G8-MIN($I$2:$I$33)) -> - | K8: =IFERROR(H8*$V$7,"") -> 17.363852 | L8: =IFERROR(IF(N8<>"","-",J8*$X$7),"") -> - | M8: 3 | N8: Liam | O8: 19 | P8: Eagles | Q8: =IF(N8<>"",K8-O8,"") -> -1.6361484 | R8: =IFERROR(IF(N8<>"",O8/K8-1,""),"") -> 0.094227273 | U8: Total VBD | V8: =SUM($H$2:$H$33) -> 126.7 | W8: Total VBD | X8: =SUM($J$2:$J$33) -> 0
A9: 49ers | B9: NFC West | C9: 10.5 | D9: 10.2 | E9: -0.5 | F9: =IFERROR(AVERAGE(D9,C9)+E9,"") -> 9.85 | G9: =F9 -> 9.85 | H9: =G9-MIN($G$2:$G$33) -> 5.4 | I9: =IF(N9<>"","-",G9) -> - | J9: =IF(N9<>"","-",G9-MIN($I$2:$I$33)) -> - | K9: =IFERROR(H9*$V$7,"") -> 17.048145 | L9: =IFERROR(IF(N9<>"","-",J9*$X$7),"") -> - | M9: 3 | N9: Evan | O9: 11 | P9: 49ers | Q9: =IF(N9<>"",K9-O9,"") -> 6.0481452 | R9: =IFERROR(IF(N9<>"",O9/K9-1,""),"") -> -0.35476852 | U9: Total Wins | V9: =SUM($G$2:$G$33) -> 269.1 | W9: Wins Left | X9: =SUM($I$2:$I$33) -> 0
A10: Broncos | B10: AFC West | C10: 9.5 | D10: 9.1 | E10: 0.5 | F10: =IFERROR(AVERAGE(D10,C10)+E10,"") -> 9.8 | G10: =F10 -> 9.8 | H10: =G10-MIN($G$2:$G$33) -> 5.35 | I10: =IF(N10<>"","-",G10) -> - | J10: =IF(N10<>"","-",G10-MIN($I$2:$I$33)) -> - | K10: =IFERROR(H10*$V$7,"") -> 16.890292 | L10: =IFERROR(IF(N10<>"","-",J10*$X$7),"") -> - | M10: 3 | N10: Rich | O10: 16 | P10: Broncos | Q10: =IF(N10<>"",K10-O10,"") -> 0.89029203 | R10: =IFERROR(IF(N10<>"",O10/K10-1,""),"") -> -0.05271028
A11: Texans | B11: AFC South | C11: 9.5 | D11: 9.8 | E11: 0 | F11: =IFERROR(AVERAGE(D11,C11)+E11,"") -> 9.65 | G11: =F11 -> 9.65 | H11: =G11-MIN($G$2:$G$33) -> 5.2 | I11: =IF(N11<>"","-",G11) -> - | J11: =IF(N11<>"","-",G11-MIN($I$2:$I$33)) -> - | K11: =IFERROR(H11*$V$7,"") -> 16.416732 | L11: =IFERROR(IF(N11<>"","-",J11*$X$7),"") -> - | M11: 3 | N11: Barry | O11: 17 | P11: Texans | Q11: =IF(N11<>"",K11-O11,"") -> -0.58326756 | R11: =IFERROR(IF(N11<>"",O11/K11-1,""),"") -> 0.035528846 | U11: Inflation | V11: =IFERROR(1+AVERAGE($R$2:$R$33),100%) -> 1.1770174
A12: Packers | B12: NFC North | C12: 10.5 | D12: 9.7 | E12: -0.5 | F12: =IFERROR(AVERAGE(D12,C12)+E12,"") -> 9.6 | G12: =F12 -> 9.6 | H12: =G12-MIN($G$2:$G$33) -> 5.15 | I12: =IF(N12<>"","-",G12) -> - | J12: =IF(N12<>"","-",G12-MIN($I$2:$I$33)) -> - | K12: =IFERROR(H12*$V$7,"") -> 16.258879 | L12: =IFERROR(IF(N12<>"","-",J12*$X$7),"") -> - | M12: 3 | N12: Sean | O12: 11 | P12: Packers | Q12: =IF(N12<>"",K12-O12,"") -> 5.2588792 | R12: =IFERROR(IF(N12<>"",O12/K12-1,""),"") -> -0.3234466
A13: Chiefs | B13: AFC West | C13: 10.5 | D13: 9.6 | E13: -0.5 | F13: =IFERROR(AVERAGE(D13,C13)+E13,"") -> 9.55 | G13: =F13 -> 9.55 | H13: =G13-MIN($G$2:$G$33) -> 5.1 | I13: =IF(N13<>"","-",G13) -> - | J13: =IF(N13<>"","-",G13-MIN($I$2:$I$33)) -> - | K13: =IFERROR(H13*$V$7,"") -> 16.101026 | L13: =IFERROR(IF(N13<>"","-",J13*$X$7),"") -> - | M13: 3 | N13: Liam | O13: 19 | P13: Chiefs | Q13: =IF(N13<>"",K13-O13,"") -> -2.898974 | R13: =IFERROR(IF(N13<>"",O13/K13-1,""),"") -> 0.18004902 | U13: Player | V13: Teams | W13: Drafted | X13: Rem | Y13: Spent | Z13: Rem | AA13: Max | AB13: Proj.
A14: Patriots | B14: AFC East | C14: 9.5 | D14: 10.3 | E14: -0.5 | F14: =IFERROR(AVERAGE(D14,C14)+E14,"") -> 9.4 | G14: =F14 -> 9.4 | H14: =G14-MIN($G$2:$G$33) -> 4.95 | I14: =IF(N14<>"","-",G14) -> - | J14: =IF(N14<>"","-",G14-MIN($I$2:$I$33)) -> - | K14: =IFERROR(H14*$V$7,"") -> 15.627466 | L14: =IFERROR(IF(N14<>"","-",J14*$X$7),"") -> - | M14: 3 | N14: Tyler | O14: 19 | P14: Patriots | Q14: =IF(N14<>"",K14-O14,"") -> -3.3725335 | R14: =IFERROR(IF(N14<>"",O14/K14-1,""),"") -> 0.21580808 | U14: Sean | V14: 4 | W14: =COUNTIFS($N$2:$N$33,$U14) -> 4 | X14: =V14-W14 -> 0 | Y14: =SUMIFS($O$2:$O$33,$N$2:$N$33,$U14) -> 50 | Z14: =$V$2-Y14 -> 0 | AA14: =IF(X14=0,0,Z14-(X14-1)) -> 0 | AB14: =SUMIFS($G$2:$G$33,$N$2:$N$33,$U14) -> 36.45
A15: Bengals | B15: AFC North | C15: 9.5 | D15: 10.3 | E15: -0.5 | F15: =IFERROR(AVERAGE(D15,C15)+E15,"") -> 9.4 | G15: =F15 -> 9.4 | H15: =G15-MIN($G$2:$G$33) -> 4.95 | I15: =IF(N15<>"","-",G15) -> - | J15: =IF(N15<>"","-",G15-MIN($I$2:$I$33)) -> - | K15: =IFERROR(H15*$V$7,"") -> 15.627466 | L15: =IFERROR(IF(N15<>"","-",J15*$X$7),"") -> - | M15: 3 | N15: Rich | O15: 17 | P15: Bengals | Q15: =IF(N15<>"",K15-O15,"") -> -1.3725335 | R15: =IFERROR(IF(N15<>"",O15/K15-1,""),"") -> 0.087828283 | U15: Rich | V15: 4 | W15: =COUNTIFS($N$2:$N$33,$U15) -> 4 | X15: =V15-W15 -> 0 | Y15: =SUMIFS($O$2:$O$33,$N$2:$N$33,$U15) -> 50 | Z15: =$V$2-Y15 -> 0 | AA15: =IF(X15=0,0,Z15-(X15-1)) -> 0 | AB15: =SUMIFS($G$2:$G$33,$N$2:$N$33,$U15) -> 33.1
A16: Jaguars | B16: AFC South | C16: 8.5 | D16: 9 | E16: 0.5 | F16: =IFERROR(AVERAGE(D16,C16)+E16,"") -> 9.25 | G16: =F16 -> 9.25 | H16: =G16-MIN($G$2:$G$33) -> 4.8 | I16: =IF(N16<>"","-",G16) -> - | J16: =IF(N16<>"","-",G16-MIN($I$2:$I$33)) -> - | K16: =IFERROR(H16*$V$7,"") -> 15.153907 | L16: =IFERROR(IF(N16<>"","-",J16*$X$7),"") -> - | M16: 4 | N16: John | O16: 14 | P16: Jaguars | Q16: =IF(N16<>"",K16-O16,"") -> 1.1539069 | R16: =IFERROR(IF(N16<>"",O16/K16-1,""),"") -> -0.076145833 | U16: Tyler | V16: 4 | W16: =COUNTIFS($N$2:$N$33,$U16) -> 4 | X16: =V16-W16 -> 0 | Y16: =SUMIFS($O$2:$O$33,$N$2:$N$33,$U16) -> 50 | Z16: =$V$2-Y16 -> 0 | AA16: =IF(X16=0,0,Z16-(X16-1)) -> 0 | AB16: =SUMIFS($G$2:$G$33,$N$2:$N$33,$U16) -> 31.1
A17: Chargers | B17: AFC West | C17: 9.5 | D17: 9.4 | E17: -0.5 | F17: =IFERROR(AVERAGE(D17,C17)+E17,"") -> 8.95 | G17: =F17 -> 8.95 | H17: =G17-MIN($G$2:$G$33) -> 4.5 | I17: =IF(N17<>"","-",G17) -> - | J17: =IF(N17<>"","-",G17-MIN($I$2:$I$33)) -> - | K17: =IFERROR(H17*$V$7,"") -> 14.206788 | L17: =IFERROR(IF(N17<>"","-",J17*$X$7),"") -> - | M17: 4 | N17: John | O17: 11 | P17: Chargers | Q17: =IF(N17<>"",K17-O17,"") -> 3.2067877 | R17: =IFERROR(IF(N17<>"",O17/K17-1,""),"") -> -0.22572222 | U17: Liam | V17: 4 | W17: =COUNTIFS($N$2:$N$33,$U17) -> 4 | X17: =V17-W17 -> 0 | Y17: =SUMIFS($O$2:$O$33,$N$2:$N$33,$U17) -> 50 | Z17: =$V$2-Y17 -> 0 | AA17: =IF(X17=0,0,Z17-(X17-1)) -> 0 | AB17: =SUMIFS($G$2:$G$33,$N$2:$N$33,$U17) -> 33
A18: Cowboys | B18: NFC East | C18: 9.5 | D18: 9.2 | E18: -0.5 | F18: =IFERROR(AVERAGE(D18,C18)+E18,"") -> 8.85 | G18: =F18 -> 8.85 | H18: =G18-MIN($G$2:$G$33) -> 4.4 | I18: =IF(N18<>"","-",G18) -> - | J18: =IF(N18<>"","-",G18-MIN($I$2:$I$33)) -> - | K18: =IFERROR(H18*$V$7,"") -> 13.891081 | L18: =IFERROR(IF(N18<>"","-",J18*$X$7),"") -> - | M18: 4 | N18: Sean | O18: 7 | P18: Cowboys | Q18: =IF(N18<>"",K18-O18,"") -> 6.8910813 | R18: =IFERROR(IF(N18<>"",O18/K18-1,""),"") -> -0.49607955 | U18: Evan | V18: 4 | W18: =COUNTIFS($N$2:$N$33,$U18) -> 4 | X18: =V18-W18 -> 0 | Y18: =SUMIFS($O$2:$O$33,$N$2:$N$33,$U18) -> 50 | Z18: =$V$2-Y18 -> 0 | AA18: =IF(X18=0,0,Z18-(X18-1)) -> 0 | AB18: =SUMIFS($G$2:$G$33,$N$2:$N$33,$U18) -> 35.15
A19: Vikings | B19: NFC North | C19: 8.5 | D19: 8.7 | E19: 0 | F19: =IFERROR(AVERAGE(D19,C19)+E19,"") -> 8.6 | G19: =F19 -> 8.6 | H19: =G19-MIN($G$2:$G$33) -> 4.15 | I19: =IF(N19<>"","-",G19) -> - | J19: =IF(N19<>"","-",G19-MIN($I$2:$I$33)) -> - | K19: =IFERROR(H19*$V$7,"") -> 13.101815 | L19: =IFERROR(IF(N19<>"","-",J19*$X$7),"") -> - | M19: 4 | N19: Evan | O19: 13 | P19: Vikings | Q19: =IF(N19<>"",K19-O19,"") -> 0.10181531 | R19: =IFERROR(IF(N19<>"",O19/K19-1,""),"") -> -0.0077710843 | U19: John | V19: 4 | W19: =COUNTIFS($N$2:$N$33,$U19) -> 4 | X19: =V19-W19 -> 0 | Y19: =SUMIFS($O$2:$O$33,$N$2:$N$33,$U19) -> 50 | Z19: =$V$2-Y19 -> 0 | AA19: =IF(X19=0,0,Z19-(X19-1)) -> 0 | AB19: =SUMIFS($G$2:$G$33,$N$2:$N$33,$U19) -> 35.9
A20: Steelers | B20: AFC North | C20: 8.5 | D20: 8.4 | E20: -0.5 | F20: =IFERROR(AVERAGE(D20,C20)+E20,"") -> 7.95 | G20: =F20 -> 7.95 | H20: =G20-MIN($G$2:$G$33) -> 3.5 | I20: =IF(N20<>"","-",G20) -> - | J20: =IF(N20<>"","-",G20-MIN($I$2:$I$33)) -> - | K20: =IFERROR(H20*$V$7,"") -> 11.049724 | L20: =IFERROR(IF(N20<>"","-",J20*$X$7),"") -> - | M20: 5 | N20: Barry | O20: 5 | P20: Steelers | Q20: =IF(N20<>"",K20-O20,"") -> 6.0497238 | R20: =IFERROR(IF(N20<>"",O20/K20-1,""),"") -> -0.5475 | U20: Barry | V20: 4 | W20: =COUNTIFS($N$2:$N$33,$U20) -> 4 | X20: =V20-W20 -> 0 | Y20: =SUMIFS($O$2:$O$33,$N$2:$N$33,$U20) -> 48 | Z20: =$V$2-Y20 -> 2 | AA20: =IF(X20=0,0,Z20-(X20-1)) -> 0 | AB20: =SUMIFS($G$2:$G$33,$N$2:$N$33,$U20) -> 34.05
A21: Buccaneers | B21: NFC South | C21: 8.5 | D21: 8 | E21: -0.5 | F21: =IFERROR(AVERAGE(D21,C21)+E21,"") -> 7.75 | G21: =F21 -> 7.75 | H21: =G21-MIN($G$2:$G$33) -> 3.3 | I21: =IF(N21<>"","-",G21) -> - | J21: =IF(N21<>"","-",G21-MIN($I$2:$I$33)) -> - | K21: =IFERROR(H21*$V$7,"") -> 10.418311 | L21: =IFERROR(IF(N21<>"","-",J21*$X$7),"") -> - | M21: 5 | N21: Rich | O21: 11 | P21: Buccaneers | Q21: =IF(N21<>"",K21-O21,"") -> -0.58168903 | R21: =IFERROR(IF(N21<>"",O21/K21-1,""),"") -> 0.055833333 | U21: Leo | V21: 4 | W21: =COUNTIFS($N$2:$N$33,$U21) -> 4 | X21: =V21-W21 -> 0 | Y21: =SUMIFS($O$2:$O$33,$N$2:$N$33,$U21) -> 49 | Z21: =$V$2-Y21 -> 1 | AA21: =IF(X21=0,0,Z21-(X21-1)) -> 0 | AB21: =SUMIFS($G$2:$G$33,$N$2:$N$33,$U21) -> 30.35
A22: Saints | B22: NFC South | C22: 7.5 | D22: 7.8 | E22: 0 | F22: =IFERROR(AVERAGE(D22,C22)+E22,"") -> 7.65 | G22: =F22 -> 7.65 | H22: =G22-MIN($G$2:$G$33) -> 3.2 | I22: =IF(N22<>"","-",G22) -> - | J22: =IF(N22<>"","-",G22-MIN($I$2:$I$33)) -> - | K22: =IFERROR(H22*$V$7,"") -> 10.102605 | L22: =IFERROR(IF(N22<>"","-",J22*$X$7),"") -> - | M22: 5 | N22: John | O22: 12 | P22: Saints | Q22: =IF(N22<>"",K22-O22,"") -> -1.8973954 | R22: =IFERROR(IF(N22<>"",O22/K22-1,""),"") -> 0.1878125
A23: Panthers | B23: NFC South | C23: 7.5 | D23: 6.7 | E23: 0.5 | F23: =IFERROR(AVERAGE(D23,C23)+E23,"") -> 7.6 | G23: =F23 -> 7.6 | H23: =G23-MIN($G$2:$G$33) -> 3.15 | I23: =IF(N23<>"","-",G23) -> - | J23: =IF(N23<>"","-",G23-MIN($I$2:$I$33)) -> - | K23: =IFERROR(H23*$V$7,"") -> 9.9447514 | L23: =IFERROR(IF(N23<>"","-",J23*$X$7),"") -> - | M23: 5 | N23: Liam | O23: 10 | P23: Panthers | Q23: =IF(N23<>"",K23-O23,"") -> -0.055248619 | R23: =IFERROR(IF(N23<>"",O23/K23-1,""),"") -> 0.0055555556
A24: Colts | B24: AFC South | C24: 7.5 | D24: 8.2 | E24: -0.5 | F24: =IFERROR(AVERAGE(D24,C24)+E24,"") -> 7.35 | G24: =F24 -> 7.35 | H24: =G24-MIN($G$2:$G$33) -> 2.9 | I24: =IF(N24<>"","-",G24) -> - | J24: =IF(N24<>"","-",G24-MIN($I$2:$I$33)) -> - | K24: =IFERROR(H24*$V$7,"") -> 9.1554854 | L24: =IFERROR(IF(N24<>"","-",J24*$X$7),"") -> - | M24: 6 | N24: Tyler | O24: 11 | P24: Colts | Q24: =IF(N24<>"",K24-O24,"") -> -1.8445146 | R24: =IFERROR(IF(N24<>"",O24/K24-1,""),"") -> 0.20146552
A25: Giants | B25: NFC East | C25: 7.5 | D25: 7.1 | E25: 0 | F25: =IFERROR(AVERAGE(D25,C25)+E25,"") -> 7.3 | G25: =F25 -> 7.3 | H25: =G25-MIN($G$2:$G$33) -> 2.85 | I25: =IF(N25<>"","-",G25) -> - | J25: =IF(N25<>"","-",G25-MIN($I$2:$I$33)) -> - | K25: =IFERROR(H25*$V$7,"") -> 8.9976322 | L25: =IFERROR(IF(N25<>"","-",J25*$X$7),"") -> - | M25: 6 | N25: Tyler | O25: 9 | P25: Giants | Q25: =IF(N25<>"",K25-O25,"") -> -0.0023677979 | R25: =IFERROR(IF(N25<>"",O25/K25-1,""),"") -> 0.00026315789
A26: Commanders | B26: NFC East | C26: 7.5 | D26: 7.6 | E26: -0.5 | F26: =IFERROR(AVERAGE(D26,C26)+E26,"") -> 7.05 | G26: =F26 -> 7.05 | H26: =G26-MIN($G$2:$G$33) -> 2.6 | I26: =IF(N26<>"","-",G26) -> - | J26: =IF(N26<>"","-",G26-MIN($I$2:$I$33)) -> - | K26: =IFERROR(H26*$V$7,"") -> 8.2083662 | L26: =IFERROR(IF(N26<>"","-",J26*$X$7),"") -> - | M26: 6 | N26: Tyler | O26: 11 | P26: Commanders | Q26: =IF(N26<>"",K26-O26,"") -> -2.7916338 | R26: =IFERROR(IF(N26<>"",O26/K26-1,""),"") -> 0.34009615
A27: Falcons | B27: NFC South | C27: 6.5 | D27: 7.1 | E27: 0 | F27: =IFERROR(AVERAGE(D27,C27)+E27,"") -> 6.8 | G27: =F27 -> 6.8 | H27: =G27-MIN($G$2:$G$33) -> 2.35 | I27: =IF(N27<>"","-",G27) -> - | J27: =IF(N27<>"","-",G27-MIN($I$2:$I$33)) -> - | K27: =IFERROR(H27*$V$7,"") -> 7.4191002 | L27: =IFERROR(IF(N27<>"","-",J27*$X$7),"") -> - | M27: 6 | N27: Sean | O27: 10 | P27: Falcons | Q27: =IF(N27<>"",K27-O27,"") -> -2.5808998 | R27: =IFERROR(IF(N27<>"",O27/K27-1,""),"") -> 0.34787234
A28: Titans | B28: AFC South | C28: 6.5 | D28: 5.8 | E28: 0 | F28: =IFERROR(AVERAGE(D28,C28)+E28,"") -> 6.15 | G28: =F28 -> 6.15 | H28: =G28-MIN($G$2:$G$33) -> 1.7 | I28: =IF(N28<>"","-",G28) -> - | J28: =IF(N28<>"","-",G28-MIN($I$2:$I$33)) -> - | K28: =IFERROR(H28*$V$7,"") -> 5.3670087 | L28: =IFERROR(IF(N28<>"","-",J28*$X$7),"") -> - | M28: 7 | N28: Rich | O28: 6 | P28: Titans | Q28: =IF(N28<>"",K28-O28,"") -> -0.63299132 | R28: =IFERROR(IF(N28<>"",O28/K28-1,""),"") -> 0.11794118
A29: Browns | B29: AFC North | C29: 6.5 | D29: 5.3 | E29: 0 | F29: =IFERROR(AVERAGE(D29,C29)+E29,"") -> 5.9 | G29: =F29 -> 5.9 | H29: =G29-MIN($G$2:$G$33) -> 1.45 | I29: =IF(N29<>"","-",G29) -> - | J29: =IF(N29<>"","-",G29-MIN($I$2:$I$33)) -> - | K29: =IFERROR(H29*$V$7,"") -> 4.5777427 | L29: =IFERROR(IF(N29<>"","-",J29*$X$7),"") -> - | M29: 7 | N29: Liam | O29: 2 | P29: Browns | Q29: =IF(N29<>"",K29-O29,"") -> 2.5777427 | R29: =IFERROR(IF(N29<>"",O29/K29-1,""),"") -> -0.56310345
A30: Raiders | B30: AFC West | C30: 5.5 | D30: 6.2 | E30: 0 | F30: =IFERROR(AVERAGE(D30,C30)+E30,"") -> 5.85 | G30: =F30 -> 5.85 | H30: =G30-MIN($G$2:$G$33) -> 1.4 | I30: =IF(N30<>"","-",G30) -> - | J30: =IF(N30<>"","-",G30-MIN($I$2:$I$33)) -> - | K30: =IFERROR(H30*$V$7,"") -> 4.4198895 | L30: =IFERROR(IF(N30<>"","-",J30*$X$7),"") -> - | M30: 7 | N30: Barry | O30: 3 | P30: Raiders | Q30: =IF(N30<>"",K30-O30,"") -> 1.4198895 | R30: =IFERROR(IF(N30<>"",O30/K30-1,""),"") -> -0.32125
A31: Jets | B31: AFC East | C31: 5.5 | D31: 5.6 | E31: 0 | F31: =IFERROR(AVERAGE(D31,C31)+E31,"") -> 5.55 | G31: =F31 -> 5.55 | H31: =G31-MIN($G$2:$G$33) -> 1.1 | I31: =IF(N31<>"","-",G31) -> - | J31: =IF(N31<>"","-",G31-MIN($I$2:$I$33)) -> - | K31: =IFERROR(H31*$V$7,"") -> 3.4727703 | L31: =IFERROR(IF(N31<>"","-",J31*$X$7),"") -> - | M31: 7 | N31: Evan | O31: 7 | P31: Jets | Q31: =IF(N31<>"",K31-O31,"") -> -3.5272297 | R31: =IFERROR(IF(N31<>"",O31/K31-1,""),"") -> 1.0156818
A32: Dolphins | B32: AFC East | C32: 4.5 | D32: 4.5 | E32: 0 | F32: =IFERROR(AVERAGE(D32,C32)+E32,"") -> 4.5 | G32: =F32 -> 4.5 | H32: =G32-MIN($G$2:$G$33) -> 0.05 | I32: =IF(N32<>"","-",G32) -> - | J32: =IF(N32<>"","-",G32-MIN($I$2:$I$33)) -> - | K32: =IFERROR(H32*$V$7,"") -> 0.1578532 | L32: =IFERROR(IF(N32<>"","-",J32*$X$7),"") -> - | M32: 8 | N32: Leo | O32: 1 | P32: Dolphins | Q32: =IF(N32<>"",K32-O32,"") -> -0.8421468 | R32: =IFERROR(IF(N32<>"",O32/K32-1,""),"") -> 5.335
A33: Cardinals | B33: NFC West | C33: 4.5 | D33: 4.4 | E33: 0 | F33: =IFERROR(AVERAGE(D33,C33)+E33,"") -> 4.45 | G33: =F33 -> 4.45 | H33: =G33-MIN($G$2:$G$33) -> 0 | I33: =IF(N33<>"","-",G33) -> - | J33: =IF(N33<>"","-",G33-MIN($I$2:$I$33)) -> - | K33: =IFERROR(H33*$V$7,"") -> 0 | L33: =IFERROR(IF(N33<>"","-",J33*$X$7),"") -> - | M33: 8 | N33: Leo | O33: 1 | P33: Cardinals | Q33: =IF(N33<>"",K33-O33,"") -> -1 | R33: =IFERROR(IF(N33<>"",O33/K33-1,""),"")

Sheet SOS
A1: Abb | B1: Season | C1: Original Rating | D1: Current Rating | E1: Win Total | F1: Total Result | G1: Projected SoS | H1: Proj Rank | I1: Played SoS | J1: Played Rank | K1: Avg. Opp. Rating | L1: Rank | M1: Team | N1: Week
A2: DET | B2: 2025 | C2: 3.91255 | D2: 3.60974 | E2: 9.5 | F2: Active | G2: 2.05598 | H2: 1 | I2: 4.75637 | J2: 5 | M2: =IF(A2<>"",IF($A2="OAK","LV",$A2),"") -> DET | N2: 1
A3: NYG | B3: 2025 | C3: -3.38349 | D3: -3.5968 | E3: 5.5 | F3: Active | G3: 1.7733 | H3: 2 | I3: 2.87775 | J3: 8 | M3: =IF(A3<>"",IF($A3="OAK","LV",$A3),"") -> NYG | N3: 1
A4: PHI | B4: 2025 | C4: 5.46796 | D4: 5.28946 | E4: 10.5 | F4: Active | G4: 1.73482 | H4: 3 | I4: -0.490711 | J4: 20 | M4: =IF(A4<>"",IF($A4="OAK","LV",$A4),"") -> PHI | N4: 1
A5: CLE | B5: 2025 | C5: -5.55016 | D5: -5.59889 | E5: 4.5 | F5: Active | G5: 1.6965 | H5: 4 | I5: 2.52532 | J5: 11 | M5: =IF(A5<>"",IF($A5="OAK","LV",$A5),"") -> CLE | N5: 1
A6: MIN | B6: 2025 | C6: 3.12496 | D6: 3.02809 | E6: 9.5 | F6: Active | G6: 1.58147 | H6: 5 | I6: -0.186668 | J6: 18 | M6: =IF(A6<>"",IF($A6="OAK","LV",$A6),"") -> MIN | N6: 1
A7: CHI | B7: 2025 | C7: -0.0390495 | D7: -0.186668 | E7: 7.5 | F7: Active | G7: 1.45756 | H7: 6 | I7: 3.02809 | J7: 7 | M7: =IF(A7<>"",IF($A7="OAK","LV",$A7),"") -> CHI | N7: 1
A8: KC | B8: 2025 | C8: 6.58069 | D8: 6.36061 | E8: 11.5 | F8: Active | G8: 1.39165 | H8: 7 | I8: 2.64577 | J8: 10 | M8: =IF(A8<>"",IF($A8="OAK","LV",$A8),"") -> KC | N8: 1
A9: DAL | B9: 2025 | C9: -0.437955 | D9: -0.490711 | E9: 7.5 | F9: Active | G9: 1.37612 | H9: 8 | I9: 5.28946 | J9: 4 | M9: =IF(A9<>"",IF($A9="OAK","LV",$A9),"") -> DAL | N9: 1
A10: GB | B10: 2025 | C10: 4.71442 | D10: 4.75637 | E10: 10.5 | F10: Active | G10: 1.32143 | H10: 9 | I10: 3.60974 | J10: 6 | M10: =IF(A10<>"",IF($A10="OAK","LV",$A10),"") -> GB | N10: 1
A11: WAS | B11: 2025 | C11: 2.896 | D11: 2.87775 | E11: 9.5 | F11: Active | G11: 1.18953 | H11: 10 | I11: -3.5968 | J11: 27 | M11: =IF(A11<>"",IF($A11="OAK","LV",$A11),"") -> WAS | N11: 1
A12: PIT | B12: 2025 | C12: 1.27518 | D12: 1.12078 | E12: 8.5 | F12: Active | G12: 1.18564 | H12: 11 | I12: -4.04083 | J12: 29 | M12: =IF(A12<>"",IF($A12="OAK","LV",$A12),"") -> PIT | N12: 1
A13: BAL | B13: 2025 | C13: 6.70286 | D13: 6.56626 | E13: 11.5 | F13: Active | G13: 1.14725 | H13: 12 | I13: 6.60627 | J13: 1 | M13: =IF(A13<>"",IF($A13="OAK","LV",$A13),"") -> BAL | N13: 1
... A33: SF | B33: 2025 | C33: 1.95396 | D33: 1.90722 | E33: 10.5 | F33: Active | G33: -1.39298 | H33: 32 | I33: -0.37984 | J33: 19 | M33: =IF(A33<>"",IF($A33="OAK","LV",$A33),"") -> SF | N33: 1
A34: DET | B34: 2025 | C34: 3.91255 | D34: 3.99942 | E34: 9.5 | F34: Active | G34: 2.05598 | H34: 1 | I34: 1.86076 | J34: 8 | M34: =IF(A34<>"",IF($A34="OAK","LV",$A34),"") -> DET | N34: =IF(A34<>"",N2+1,"") -> 2
A35: NYG | B35: 2025 | C35: -3.38349 | D35: -3.78261 | E35: 5.5 | F35: Active | G35: 1.7733 | H35: 2 | I35: 1.02052 | J35: 14 | M35: =IF(A35<>"",IF($A35="OAK","LV",$A35),"") -> NYG | N35: =IF(A35<>"",N3+1,"") -> 2
A36: PHI | B36: 2025 | C36: 5.46796 | D36: 5.26347 | E36: 10.5 | F36: Active | G36: 1.73482 | H36: 3 | I36: 2.65603 | J36: 6 | M36: =IF(A36<>"",IF($A36="OAK","LV",$A36),"") -> PHI | N36: =IF(A36<>"",N4+1,"") -> 2
A37: CLE | B37: 2025 | C37: -5.55016 | D37: -6.03012 | E37: 4.5 | F37: Active | G37: 1.6965 | H37: 4 | I37: 4.43942 | J37: 1 | M37: =IF(A37<>"",IF($A37="OAK","LV",$A37),"") -> CLE | N37: =IF(A37<>"",N5+1,"") -> 2
A38: MIN | B38: 2025 | C38: 3.12496 | D38: 2.17622 | E38: 9.5 | F38: Active | G38: 1.58147 | H38: 5 | I38: -1.56299 | J38: 26 | M38: =IF(A38<>"",IF($A38="OAK","LV",$A38),"") -> MIN | N38: =IF(A38<>"",N6+1,"") -> 2
A39: CHI | B39: 2025 | C39: -0.0390495 | D39: -1.17929 | E39: 7.5 | F39: Active | G39: 1.45756 | H39: 6 | I39: 3.08782 | J39: 5 | M39: =IF(A39<>"",IF($A39="OAK","LV",$A39),"") -> CHI | N39: =IF(A39<>"",N7+1,"") -> 2
A40: KC | B40: 2025 | C40: 6.58069 | D40: 5.97802 | E40: 11.5 | F40: Active | G40: 1.39165 | H40: 7 | I40: 4.05546 | J40: 2 | M40: =IF(A40<>"",IF($A40="OAK","LV",$A40),"") -> KC | N40: =IF(A40<>"",N8+1,"") -> 2
A41: DAL | B41: 2025 | C41: -0.437955 | D41: -0.665967 | E41: 7.5 | F41: Active | G41: 1.37612 | H41: 8 | I41: 0.740427 | J41: 15 | M41: =IF(A41<>"",IF($A41="OAK","LV",$A41),"") -> DAL | N41: =IF(A41<>"",N9+1,"") -> 2
A42: GB | B42: 2025 | C42: 4.71442 | D42: 4.90081 | E42: 10.5 | F42: Active | G42: 1.32143 | H42: 9 | I42: 3.35321 | J42: 4 | M42: =IF(A42<>"",IF($A42="OAK","LV",$A42),"") -> GB | N42: =IF(A42<>"",N10+1,"") -> 2
A43: WAS | B43: 2025 | C43: 2.896 | D43: 2.707 | E43: 9.5 | F43: Active | G43: 1.18953 | H43: 10 | I43: 0.5591 | J43: 17 | M43: =IF(A43<>"",IF($A43="OAK","LV",$A43),"") -> WAS | N43: =IF(A43<>"",N11+1,"") -> 2
A44: PIT | B44: 2025 | C44: 1.27518 | D44: 0.388884 | E44: 8.5 | F44: Active | G44: 1.18564 | H44: 11 | I44: -2.24011 | J44: 27 | M44: =IF(A44<>"",IF($A44="OAK","LV",$A44),"") -> PIT | N44: =IF(A44<>"",N12+1,"") -> 2
A45: BAL | B45: 2025 | C45: 6.70286 | D45: 6.68215 | E45: 11.5 | F45: Active | G45: 1.14725 | H45: 12 | I45: 0.376736 | J45: 18 | M45: =IF(A45<>"",IF($A45="OAK","LV",$A45),"") -> BAL | N45: =IF(A45<>"",N13+1,"") -> 2
... A65: SF | B65: 2025 | C65: 1.95396 | D65: 1.93297 | E65: 10.5 | F65: Active | G65: -1.39298 | H65: 32 | I65: -4.12265 | J65: 31 | M65: =IF(A65<>"",IF($A65="OAK","LV",$A65),"") -> SF | N65: =IF(A65<>"",N33+1,"") -> 2
M66: =IF(A66<>"",IF($A66="OAK","LV",$A66),"") | N66: =IF(A66<>"",N34+1,"")
M67: =IF(A67<>"",IF($A67="OAK","LV",$A67),"") | N67: =IF(A67<>"",N35+1,"")
M68: =IF(A68<>"",IF($A68="OAK","LV",$A68),"") | N68: =IF(A68<>"",N36+1,"")
M69: =IF(A69<>"",IF($A69="OAK","LV",$A69),"") | N69: =IF(A69<>"",N37+1,"")
M70: =IF(A70<>"",IF($A70="OAK","LV",$A70),"") | N70: =IF(A70<>"",N38+1,"")
M71: =IF(A71<>"",IF($A71="OAK","LV",$A71),"") | N71: =IF(A71<>"",N39+1,"")
M72: =IF(A72<>"",IF($A72="OAK","LV",$A72),"") | N72: =IF(A72<>"",N40+1,"")
M73: =IF(A73<>"",IF($A73="OAK","LV",$A73),"") | N73: =IF(A73<>"",N41+1,"")
M74: =IF(A74<>"",IF($A74="OAK","LV",$A74),"") | N74: =IF(A74<>"",N42+1,"")
M75: =IF(A75<>"",IF($A75="OAK","LV",$A75),"") | N75: =IF(A75<>"",N43+1,"")
M76: =IF(A76<>"",IF($A76="OAK","LV",$A76),"") | N76: =IF(A76<>"",N44+1,"")
M77: =IF(A77<>"",IF($A77="OAK","LV",$A77),"") | N77: =IF(A77<>"",N45+1,"")
... M225: =IF(A225<>"",IF($A225="OAK","LV",$A225),"") | N225: =IF(A225<>"",N193+1,"")

Sheet Value
A1: Team | B1: Ab | C1: Division | D1: O/U | E1: Projected | F1: Drafted by | G1: Round | H1: Paid | I1: Value | J1: Wins | K1: Losses | L1: Ties | M1: Current Value | N1: New VOR | O1: Bye? | P1: Check | R1: Check | U1: Player | V1: W | W1: L | X1: T | Y1: %
A2: Broncos | B2: DEN | C2: AFC West | D2: 9.5 | E2: 15.625 | F2: John | G2: 1 | H2: 17 | I2: =M2-H2 -> 8.1428571 | J2: 14 | K2: 3 | L2: 0 | M2: =IFERROR(IF(N2*($S$7/SUM($N$2:$N$33))>47,47,N2*($S$7/SUM($N$2:$N$33))),"") -> 25.142857 | N2: =J2-MIN($J$2:$J$33) -> 11 | O2: Yes | P2: =SUM(J2:L2) -> 17 | R2: Wins | S2: =SUM(J2:J33) -> 271 | U2: John | V2: =SUMIFS(J$2:J$33,$F$2:$F$33,$U2) -> 43 | W2: =SUMIFS(K$2:K$33,$F$2:$F$33,$U2) -> 25 | X2: =SUMIFS(L$2:L$33,$F$2:$F$33,$U2) -> 0 | Y2: =V2/SUM(V2:W2) -> 0.63235294
A3: Patriots | B3: NE | C3: AFC East | D3: 8.5 | E3: 12.5 | F3: John | G3: 3 | H3: 10 | I3: =M3-H3 -> 15.142857 | J3: 14 | K3: 3 | L3: 0 | M3: =IFERROR(IF(N3*($S$7/SUM($N$2:$N$33))>47,47,N3*($S$7/SUM($N$2:$N$33))),"") -> 25.142857 | N3: =J3-MIN($J$2:$J$33) -> 11 | O3: Yes | P3: =SUM(J3:L3) -> 17 | R3: Losses | S3: =SUM(K2:K33) -> 271 | U3: Sean | V3: =SUMIFS(J$2:J$33,$F$2:$F$33,$U3) -> 42 | W3: =SUMIFS(K$2:K$33,$F$2:$F$33,$U3) -> 26 | X3: =SUMIFS(L$2:L$33,$F$2:$F$33,$U3) -> 0 | Y3: =V3/SUM(V3:W3) -> 0.61764706
A4: Seahawks | B4: SEA | C4: NFC West | D4: 8.5 | E4: 12.5 | F4: Sean | G4: 4 | H4: 11 | I4: =M4-H4 -> 14.142857 | J4: 14 | K4: 3 | L4: 0 | M4: =IFERROR(IF(N4*($S$7/SUM($N$2:$N$33))>47,47,N4*($S$7/SUM($N$2:$N$33))),"") -> 25.142857 | N4: =J4-MIN($J$2:$J$33) -> 11 | O4: Yes | P4: =SUM(J4:L4) -> 17 | U4: Barry | V4: =SUMIFS(J$2:J$33,$F$2:$F$33,$U4) -> 41 | W4: =SUMIFS(K$2:K$33,$F$2:$F$33,$U4) -> 25 | X4: =SUMIFS(L$2:L$33,$F$2:$F$33,$U4) -> 2 | Y4: =V4/SUM(V4:W4) -> 0.62121212
A5: Jaguars | B5: JAX | C5: AFC South | D5: 7.5 | E5: 9.375 | F5: Barry | G5: 3 | H5: 10 | I5: =M5-H5 -> 12.857143 | J5: 13 | K5: 4 | L5: 0 | M5: =IFERROR(IF(N5*($S$7/SUM($N$2:$N$33))>47,47,N5*($S$7/SUM($N$2:$N$33))),"") -> 22.857143 | N5: =J5-MIN($J$2:$J$33) -> 10 | O5: Yes | P5: =SUM(J5:L5) -> 17 | R5: Teams | S5: 8 | U5: Liam | V5: =SUMIFS(J$2:J$33,$F$2:$F$33,$U5) -> 0 | W5: =SUMIFS(K$2:K$33,$F$2:$F$33,$U5) -> 0 | X5: =SUMIFS(L$2:L$33,$F$2:$F$33,$U5) -> 0 | Y5: =V5/SUM(V5:W5) -> #DIV/0!
A6: 49ers | B6: SF | C6: NFC West | D6: 10.5 | E6: 18.75 | F6: Evan | G6: 1 | H6: 18 | I6: =M6-H6 -> 2.5714286 | J6: 12 | K6: 5 | L6: 0 | M6: =IFERROR(IF(N6*($S$7/SUM($N$2:$N$33))>47,47,N6*($S$7/SUM($N$2:$N$33))),"") -> 20.571429 | N6: =J6-MIN($J$2:$J$33) -> 9 | O6: Yes | P6: =SUM(J6:L6) -> 17 | R6: Budget | S6: 50 | U6: Evan | V6: =SUMIFS(J$2:J$33,$F$2:$F$33,$U6) -> 35 | W6: =SUMIFS(K$2:K$33,$F$2:$F$33,$U6) -> 33 | X6: =SUMIFS(L$2:L$33,$F$2:$F$33,$U6) -> 0 | Y6: =V6/SUM(V6:W6) -> 0.51470588
A7: Rams | B7: LAR | C7: NFC West | D7: 9.5 | E7: 15.625 | F7: Barry | G7: 2 | H7: 15 | I7: =M7-H7 -> 5.5714286 | J7: 12 | K7: 5 | L7: 0 | M7: =IFERROR(IF(N7*($S$7/SUM($N$2:$N$33))>47,47,N7*($S$7/SUM($N$2:$N$33))),"") -> 20.571429 | N7: =J7-MIN($J$2:$J$33) -> 9 | O7: Yes | P7: =SUM(J7:L7) -> 17 | R7: Total | S7: =S5*S6 -> 400 | U7: Leo | V7: =SUMIFS(J$2:J$33,$F$2:$F$33,$U7) -> 33 | W7: =SUMIFS(K$2:K$33,$F$2:$F$33,$U7) -> 35 | X7: =SUMIFS(L$2:L$33,$F$2:$F$33,$U7) -> 0 | Y7: =V7/SUM(V7:W7) -> 0.48529412
A8: Texans | B8: HOU | C8: AFC South | D8: 9.5 | E8: 15.625 | F8: Evan | G8: 2 | H8: 17 | I8: =M8-H8 -> 3.5714286 | J8: 12 | K8: 5 | L8: 0 | M8: =IFERROR(IF(N8*($S$7/SUM($N$2:$N$33))>47,47,N8*($S$7/SUM($N$2:$N$33))),"") -> 20.571429 | N8: =J8-MIN($J$2:$J$33) -> 9 | O8: Yes | P8: =SUM(J8:L8) -> 17 | U8: Tyler | V8: =SUMIFS(J$2:J$33,$F$2:$F$33,$U8) -> 31 | W8: =SUMIFS(K$2:K$33,$F$2:$F$33,$U8) -> 37 | X8: =SUMIFS(L$2:L$33,$F$2:$F$33,$U8) -> 0 | Y8: =V8/SUM(V8:W8) -> 0.45588235
A9: Bills | B9: BUF | C9: AFC East | D9: 11.5 | E9: 21.875 | F9: Leo | G9: 1 | H9: 24 | I9: =M9-H9 -> -3.4285714 | J9: 12 | K9: 5 | L9: 0 | M9: =IFERROR(IF(N9*($S$7/SUM($N$2:$N$33))>47,47,N9*($S$7/SUM($N$2:$N$33))),"") -> 20.571429 | N9: =J9-MIN($J$2:$J$33) -> 9 | O9: Yes | P9: =SUM(J9:L9) -> 17 | U9: Rich | V9: =SUMIFS(J$2:J$33,$F$2:$F$33,$U9) -> 21 | W9: =SUMIFS(K$2:K$33,$F$2:$F$33,$U9) -> 47 | X9: =SUMIFS(L$2:L$33,$F$2:$F$33,$U9) -> 0 | Y9: =V9/SUM(V9:W9) -> 0.30882353
A10: Bears | B10: CHI | C10: NFC North | D10: 8.5 | E10: 12.5 | F10: Niels | G10: 3 | H10: 4 | I10: =M10-H10 -> 14.285714 | J10: 11 | K10: 6 | L10: 0 | M10: =IFERROR(IF(N10*($S$7/SUM($N$2:$N$33))>47,47,N10*($S$7/SUM($N$2:$N$33))),"") -> 18.285714 | N10: =J10-MIN($J$2:$J$33) -> 8 | O10: Yes | P10: =SUM(J10:L10) -> 17 | V10: =SUM(V2:V9) -> 246 | W10: =SUM(W2:W9) -> 228 | X10: =SUM(X2:X9) -> 2
A11: Chargers | B11: LAC | C11: AFC West | D11: 9.5 | E11: 15.625 | F11: Sean | G11: 2 | H11: 13 | I11: =M11-H11 -> 5.2857143 | J11: 11 | K11: 6 | L11: 0 | M11: =IFERROR(IF(N11*($S$7/SUM($N$2:$N$33))>47,47,N11*($S$7/SUM($N$2:$N$33))),"") -> 18.285714 | N11: =J11-MIN($J$2:$J$33) -> 8 | O11: Yes | P11: =SUM(J11:L11) -> 17
A12: Eagles | B12: PHI | C12: NFC East | D12: 11.5 | E12: 21.875 | F12: Tyler | G12: 1 | H12: 23 | I12: =M12-H12 -> -4.7142857 | J12: 11 | K12: 6 | L12: 0 | M12: =IFERROR(IF(N12*($S$7/SUM($N$2:$N$33))>47,47,N12*($S$7/SUM($N$2:$N$33))),"") -> 18.285714 | N12: =J12-MIN($J$2:$J$33) -> 8 | O12: Yes | P12: =SUM(J12:L12) -> 17
A13: Packers | B13: GB | C13: NFC North | D13: 10.5 | E13: 18.75 | F13: Barry | G13: 1 | H13: 17 | I13: =M13-H13 -> -3.2857143 | J13: 9 | K13: 7 | L13: 1 | M13: =IFERROR(IF(N13*($S$7/SUM($N$2:$N$33))>47,47,N13*($S$7/SUM($N$2:$N$33))),"") -> 13.714286 | N13: =J13-MIN($J$2:$J$33) -> 6 | O13: Yes | P13: =SUM(J13:L13) -> 17
A14: Steelers | B14: PIT | C14: AFC North | D14: 8.5 | E14: 12.5 | F14: Leo | G14: 2 | H14: 14 | I14: =M14-H14 -> 2 | J14: 10 | K14: 7 | L14: 0 | M14: =IFERROR(IF(N14*($S$7/SUM($N$2:$N$33))>47,47,N14*($S$7/SUM($N$2:$N$33))),"") -> 16 | N14: =J14-MIN($J$2:$J$33) -> 7 | O14: Yes | P14: =SUM(J14:L14) -> 17
A15: Panthers | B15: CAR | C15: NFC South | D15: 6.5 | E15: 6.25 | F15: Leo | G15: 3 | H15: 3 | I15: =M15-H15 -> 8.4285714 | J15: 8 | K15: 9 | L15: 0 | M15: =IFERROR(IF(N15*($S$7/SUM($N$2:$N$33))>47,47,N15*($S$7/SUM($N$2:$N$33))),"") -> 11.428571 | N15: =J15-MIN($J$2:$J$33) -> 5 | O15: Yes | P15: =SUM(J15:L15) -> 17
A16: Vikings | B16: MIN | C16: NFC North | D16: 8.5 | E16: 12.5 | F16: Sean | G16: 1 | H16: 14 | I16: =M16-H16 -> -0.28571429 | J16: 9 | K16: 8 | L16: 0 | M16: =IFERROR(IF(N16*($S$7/SUM($N$2:$N$33))>47,47,N16*($S$7/SUM($N$2:$N$33))),"") -> 13.714286 | N16: =J16-MIN($J$2:$J$33) -> 6 | O16: Yes | P16: =SUM(J16:L16) -> 17
A17: Colts | B17: IND | C17: AFC South | D17: 7.5 | E17: 9.375 | F17: Tyler | G17: 3 | H17: 1 | I17: =M17-H17 -> 10.428571 | J17: 8 | K17: 9 | L17: 0 | M17: =IFERROR(IF(N17*($S$7/SUM($N$2:$N$33))>47,47,N17*($S$7/SUM($N$2:$N$33))),"") -> 11.428571 | N17: =J17-MIN($J$2:$J$33) -> 5 | O17: Yes | P17: =SUM(J17:L17) -> 17
A18: Lions | B18: DET | C18: NFC North | D18: 10.5 | E18: 18.75 | F18: Tyler | G18: 2 | H18: 19 | I18: =M18-H18 -> -5.2857143 | J18: 9 | K18: 8 | L18: 0 | M18: =IFERROR(IF(N18*($S$7/SUM($N$2:$N$33))>47,47,N18*($S$7/SUM($N$2:$N$33))),"") -> 13.714286 | N18: =J18-MIN($J$2:$J$33) -> 6 | O18: Yes | P18: =SUM(J18:L18) -> 17
A19: Ravens | B19: BAL | C19: AFC North | D19: 11.5 | E19: 21.875 | F19: Niels | G19: 1 | H19: 25 | I19: =M19-H19 -> -13.571429 | J19: 8 | K19: 9 | L19: 0 | M19: =IFERROR(IF(N19*($S$7/SUM($N$2:$N$33))>47,47,N19*($S$7/SUM($N$2:$N$33))),"") -> 11.428571 | N19: =J19-MIN($J$2:$J$33) -> 5 | O19: Yes | P19: =SUM(J19:L19) -> 17
A20: Cowboys | B20: DAL | C20: NFC East | D20: 7.5 | E20: 9.375 | F20: Barry | G20: 4 | H20: 8 | I20: =M20-H20 -> 1.1428571 | J20: 7 | K20: 9 | L20: 1 | M20: =IFERROR(IF(N20*($S$7/SUM($N$2:$N$33))>47,47,N20*($S$7/SUM($N$2:$N$33))),"") -> 9.1428571 | N20: =J20-MIN($J$2:$J$33) -> 4 | O20: Yes | P20: =SUM(J20:L20) -> 17
A21: Buccaneers | B21: TB | C21: NFC South | D21: 9.5 | E21: 15.625 | F21: John | G21: 2 | H21: 15 | I21: =M21-H21 -> -3.5714286 | J21: 8 | K21: 9 | L21: 0 | M21: =IFERROR(IF(N21*($S$7/SUM($N$2:$N$33))>47,47,N21*($S$7/SUM($N$2:$N$33))),"") -> 11.428571 | N21: =J21-MIN($J$2:$J$33) -> 5 | O21: Yes | P21: =SUM(J21:L21) -> 17
A22: Dolphins | B22: MIA | C22: AFC East | D22: 7.5 | E22: 9.375 | F22: John | G22: 4 | H22: 8 | I22: =M22-H22 -> 1.1428571 | J22: 7 | K22: 10 | L22: 0 | M22: =IFERROR(IF(N22*($S$7/SUM($N$2:$N$33))>47,47,N22*($S$7/SUM($N$2:$N$33))),"") -> 9.1428571 | N22: =J22-MIN($J$2:$J$33) -> 4 | O22: Yes | P22: =SUM(J22:L22) -> 17
... A33: Raiders | B33: LV | C33: AFC West | D33: 6.5 | E33: 6.25 | F33: Leo | G33: 4 | H33: 9 | I33: =M33-H33 -> -9 | J33: 3 | K33: 14 | L33: 0 | M33: =IFERROR(IF(N33*($S$7/SUM($N$2:$N$33))>47,47,N33*($S$7/SUM($N$2:$N$33))),"") -> 0 | N33: =J33-MIN($J$2:$J$33) -> 0 | O33: Yes | P33: =SUM(J33:L33) -> 17

Sheet Timeline
A1: Team | B1: Ab | C1: Division | D1: O/U | E1: Projected | F1: Drafted by | G1: Round | H1: Paid | I1: Value | J1: Wins | K1: Losses | L1: Ties | M1: Current Value | N1: New VOR | O1: Bye? | P1: Check | Q1: Week
A2: 49ers | B2: SF | C2: NFC West | D2: 10.5 | E2: 18.75 | F2: Evan | G2: 1 | H2: 18 | I2: 0.75 | J2: 0 | K2: 0 | L2: 0 | N2: 0 | O2: No | P2: 0 | Q2: 0
A3: Bears | B3: CHI | C3: NFC North | D3: 8.5 | E3: 12.5 | F3: Niels | G3: 3 | H3: 4 | I3: 8.5 | J3: 0 | K3: 0 | L3: 0 | N3: 0 | O3: No | P3: 0 | Q3: 0
A4: Bengals | B4: CIN | C4: AFC North | D4: 9.5 | E4: 15.625 | F4: Evan | G4: 3 | H4: 14 | I4: 1.625 | J4: 0 | K4: 0 | L4: 0 | N4: 0 | O4: No | P4: 0 | Q4: 0
A5: Bills | B5: BUF | C5: AFC East | D5: 11.5 | E5: 21.875 | F5: Leo | G5: 1 | H5: 24 | I5: -2.125 | J5: 0 | K5: 0 | L5: 0 | N5: 0 | O5: No | P5: 0 | Q5: 0
A6: Broncos | B6: DEN | C6: AFC West | D6: 9.5 | E6: 15.625 | F6: John | G6: 1 | H6: 17 | I6: -1.375 | J6: 0 | K6: 0 | L6: 0 | N6: 0 | O6: No | P6: 0 | Q6: 0
A7: Browns | B7: CLE | C7: AFC North | D7: 4.5 | E7: 0 | F7: Evan | G7: 4 | H7: 1 | I7: -1 | J7: 0 | K7: 0 | L7: 0 | N7: 0 | O7: No | P7: 0 | Q7: 0
A8: Buccaneers | B8: TB | C8: NFC South | D8: 9.5 | E8: 15.625 | F8: John | G8: 2 | H8: 15 | I8: 0.625 | J8: 0 | K8: 0 | L8: 0 | N8: 0 | O8: No | P8: 0 | Q8: 0
A9: Cardinals | B9: ARI | C9: NFC West | D9: 8.5 | E9: 12.5 | F9: Niels | G9: 2 | H9: 12 | I9: 0.5 | J9: 0 | K9: 0 | L9: 0 | N9: 0 | O9: No | P9: 0 | Q9: 0
A10: Chargers | B10: LAC | C10: AFC West | D10: 9.5 | E10: 15.625 | F10: Sean | G10: 2 | H10: 13 | I10: 2.625 | J10: 0 | K10: 0 | L10: 0 | N10: 0 | O10: No | P10: 0 | Q10: 0
A11: Chiefs | B11: KC | C11: AFC West | D11: 11.5 | E11: 21.875 | F11: Rich | G11: 1 | H11: 24 | I11: -2.125 | J11: 0 | K11: 0 | L11: 0 | N11: 0 | O11: No | P11: 0 | Q11: 0
A12: Colts | B12: IND | C12: AFC South | D12: 7.5 | E12: 9.375 | F12: Tyler | G12: 3 | H12: 1 | I12: 8.375 | J12: 0 | K12: 0 | L12: 0 | N12: 0 | O12: No | P12: 0 | Q12: 0
A13: Commanders | B13: WAS | C13: NFC East | D13: 9.5 | E13: 15.625 | F13: Rich | G13: 2 | H13: 19 | I13: -3.375 | J13: 0 | K13: 0 | L13: 0 | N13: 0 | O13: No | P13: 0 | Q13: 0
... A33: Vikings | B33: MIN | C33: NFC North | D33: 8.5 | E33: 12.5 | F33: Sean | G33: 1 | H33: 14 | I33: -1.5 | J33: 0 | K33: 0 | L33: 0 | N33: 0 | O33: No | P33: 0 | Q33: 0
A34: Jaguars | B34: JAX | C34: AFC South | D34: 7.5 | E34: 9.375 | F34: Barry | G34: 3 | H34: 10 | I34: -0.625 | J34: 1 | K34: 0 | L34: 0 | M34: 25 | N34: 1 | O34: No | P34: 1 | Q34: 1
A35: Packers | B35: GB | C35: NFC North | D35: 10.5 | E35: 18.75 | F35: Barry | G35: 1 | H35: 17 | I35: 1.75 | J35: 1 | K35: 0 | L35: 0 | M35: 25 | N35: 1 | O35: No | P35: 1 | Q35: 1
A36: Rams | B36: LAR | C36: NFC West | D36: 9.5 | E36: 15.625 | F36: Barry | G36: 2 | H36: 15 | I36: 0.625 | J36: 1 | K36: 0 | L36: 0 | M36: 25 | N36: 1 | O36: No | P36: 1 | Q36: 1
A37: 49ers | B37: SF | C37: NFC West | D37: 10.5 | E37: 18.75 | F37: Evan | G37: 1 | H37: 18 | I37: 0.75 | J37: 1 | K37: 0 | L37: 0 | M37: 25 | N37: 1 | O37: No | P37: 1 | Q37: 1
A38: Bengals | B38: CIN | C38: AFC North | D38: 9.5 | E38: 15.625 | F38: Evan | G38: 3 | H38: 14 | I38: 1.625 | J38: 1 | K38: 0 | L38: 0 | M38: 25 | N38: 1 | O38: No | P38: 1 | Q38: 1
A39: Broncos | B39: DEN | C39: AFC West | D39: 9.5 | E39: 15.625 | F39: John | G39: 1 | H39: 17 | I39: -1.375 | J39: 1 | K39: 0 | L39: 0 | M39: 25 | N39: 1 | O39: No | P39: 1 | Q39: 1
A40: Buccaneers | B40: TB | C40: NFC South | D40: 9.5 | E40: 15.625 | F40: John | G40: 2 | H40: 15 | I40: 0.625 | J40: 1 | K40: 0 | L40: 0 | M40: 25 | N40: 1 | O40: No | P40: 1 | Q40: 1
A41: Bills | B41: BUF | C41: AFC East | D41: 11.5 | E41: 21.875 | F41: Leo | G41: 1 | H41: 24 | I41: -2.125 | J41: 1 | K41: 0 | L41: 0 | M41: 25 | N41: 1 | O41: No | P41: 1 | Q41: 1
A42: Raiders | B42: LV | C42: AFC West | D42: 6.5 | E42: 6.25 | F42: Leo | G42: 4 | H42: 9 | I42: -2.75 | J42: 1 | K42: 0 | L42: 0 | M42: 25 | N42: 1 | O42: No | P42: 1 | Q42: 1
A43: Steelers | B43: PIT | C43: AFC North | D43: 8.5 | E43: 12.5 | F43: Leo | G43: 2 | H43: 14 | I43: -1.5 | J43: 1 | K43: 0 | L43: 0 | M43: 25 | N43: 1 | O43: No | P43: 1 | Q43: 1
A44: Cardinals | B44: ARI | C44: NFC West | D44: 8.5 | E44: 12.5 | F44: Niels | G44: 2 | H44: 12 | I44: 0.5 | J44: 1 | K44: 0 | L44: 0 | M44: 25 | N44: 1 | O44: No | P44: 1 | Q44: 1
A45: Commanders | B45: WAS | C45: NFC East | D45: 9.5 | E45: 15.625 | F45: Rich | G45: 2 | H45: 19 | I45: -3.375 | J45: 1 | K45: 0 | L45: 0 | M45: 25 | N45: 1 | O45: No | P45: 1 | Q45: 1
... A609: Raiders | B609: LV | C609: AFC West | D609: 6.5 | E609: 6.25 | F609: Leo | G609: 4 | H609: 9 | I609: -9 | J609: 3 | K609: 14 | L609: 0 | M609: 0 | N609: 0 | O609: Yes | P609: 17 | Q609: 18

Sheet EPA
A1: Team | B1: Old Season | C1: nfelo | D1: QB Adj | E1: Value | F1: WoW | G1: YTD | H1: Off Play | I1: Off Pass | J1: Off Rush | K1: Def Play | L1: Def Pass | M1: Def Rush | N1: EPA | O1: For | P1: Against | Q1: Dif | R1: Wins | S1: Pythag | T1: Elo | U1: Film | V1: Abb | W1: Week | X1: Season
A2: PHI | B2: 2024 | C2: 1711.34 | D2: 3.2932 | E2: 7.69187 | F2: 1.74355 | G2: 7.15094 | H2: 0.111 | I2: 0.1479 | J2: 0.0808176 | K2: -0.0928 | L2: -0.1084 | M2: -0.117191 | N2: 0.2038 | O2: 28.9524 | P2: 18.0952 | Q2: 10.8571 | R2: 18 | S2: 15.81 | T2: 13.2864 | U2: 15 | V2: =IF(A2="OAK","LV",A2) -> PHI | W2: 0 | X2: 2025
A3: DET | B3: 2024 | C3: 1735.27 | D3: 27.5373 | E3: 8.64903 | F3: 0 | G3: 5.53132 | H3: 0.1706 | I3: 0.2562 | J3: 0.0378555 | K3: -0.0265 | L3: -0.0577 | M3: -0.0157102 | N3: 0.1971 | O3: 33.0556 | P3: 21.5 | Q3: 11.5556 | R3: 15 | S3: 13.2275 | T3: 12.4417 | U3: 16 | V3: =IF(A3="OAK","LV",A3) -> DET | W3: 0 | X3: 2025
A4: BUF | B4: 2024 | C4: 1695.14 | D4: 27.423 | E4: 7.04388 | F4: 0 | G4: 2.41738 | H4: 0.1857 | I4: 0.2549 | J4: 0.0973198 | K4: 0.0099 | L4: 0.0652 | M4: -0.0747704 | N4: 0.1758 | O4: 30.6 | P4: 21.6 | Q4: 9 | R4: 15 | S4: 13.908 | T4: 13.7286 | U4: 11 | V4: =IF(A4="OAK","LV",A4) -> BUF | W4: 0 | X4: 2025
A5: BAL | B5: 2024 | C5: 1781.94 | D5: 43.1511 | E5: 10.5159 | F5: 0 | G5: 6.3018 | H5: 0.1863 | I5: 0.3325 | J5: 0.103777 | K5: 0.0215 | L5: 0.0045 | M5: -0.11665 | N5: 0.1648 | O5: 30.0526 | P5: 21.1579 | Q5: 8.8947 | R5: 13 | S5: 13.2377 | T5: 12.3142 | U5: 13 | V5: =IF(A5="OAK","LV",A5) -> BAL | W5: 0 | X5: 2025
A6: GB | B6: 2024 | C6: 1634.51 | D6: -6.775 | E6: 4.61835 | F6: 0 | G6: 2.98089 | H6: 0.076 | I6: 0.122 | J6: 0.00912193 | K6: -0.0504 | L6: -0.0604 | M6: -0.0790944 | N6: 0.1264 | O6: 26.1111 | P6: 20 | Q6: 6.1111 | R6: 11 | S6: 11.7526 | T6: 10.6101 | U6: 8 | V6: =IF(A6="OAK","LV",A6) -> GB | W6: 0 | X6: 2025
A7: TB | B7: 2024 | C7: 1581.23 | D7: 41.1344 | E7: 2.48733 | F7: 0 | G7: 3.4315 | H7: 0.133 | I7: 0.204 | J7: 0.0234498 | K7: 0.0169 | L7: 0.0623 | M7: -0.0529915 | N7: 0.1161 | O7: 29 | P7: 22.6667 | Q7: 6.3333 | R7: 10 | S7: 11.5556 | T7: 10.3865 | U7: 10 | V7: =IF(A7="OAK","LV",A7) -> TB | W7: 0 | X7: 2025
A8: MIN | B8: 2024 | C8: 1610.35 | D8: 10.6549 | E8: 3.6523 | F8: 0 | G8: 4.85298 | H8: 0.0103 | I8: 0.0226 | J8: -0.0679919 | K8: -0.0909 | L8: -0.0455 | M8: -0.159888 | N8: 0.1013 | O8: 24.5 | P8: 19.9444 | Q8: 4.5556 | R8: 14 | S8: 11.1516 | T8: 10.8361 | U8: 13 | V8: =IF(A8="OAK","LV",A8) -> MIN | W8: 0 | X8: 2025
A9: DEN | B9: 2024 | C9: 1659.29 | D9: 39.3647 | E9: 5.60983 | F9: 0 | G9: 8.95976 | H9: 0.026 | I9: 0.0324 | J9: -0.0328018 | K9: -0.0713 | L9: -0.1035 | M9: -0.0992789 | N9: 0.0973 | O9: 24 | P9: 19 | Q9: 5 | R9: 10 | S9: 11.4297 | T9: 8.96083 | U9: 11 | V9: =IF(A9="OAK","LV",A9) -> DEN | W9: 0 | X9: 2025
A10: LAC | B10: 2024 | C10: 1624.07 | D10: 14.5642 | E10: 4.20095 | F10: 0 | G10: 6.20302 | H10: 0.0232 | I10: 0.0543 | J10: -0.0615606 | K10: -0.0699 | L10: -0.08 | M10: -0.0686461 | N10: 0.093 | O10: 23 | P10: 18.5 | Q10: 4.5 | R10: 11 | S10: 11.2718 | T10: 9.37053 | U10: 12 | V10: =IF(A10="OAK","LV",A10) -> LAC | W10: 0 | X10: 2025
A11: WAS | B11: 2024 | C11: 1599.8 | D11: 36.3812 | E11: 3.2303 | F11: 0 | G11: 8.04575 | H11: 0.1482 | I11: 0.1483 | J11: 0.100921 | K11: 0.0779 | L11: 0.0583 | M11: 0.00228313 | N11: 0.0703 | O11: 28.8 | P11: 24.85 | Q11: 3.95 | R11: 14 | S11: 11.7305 | T11: 8.81049 | U11: 10 | V11: =IF(A11="OAK","LV",A11) -> WAS | W11: 0 | X11: 2025
A12: KC | B12: 2024 | C12: 1626.31 | D12: 16.2141 | E12: 4.29031 | F12: 1.34927 | G12: -1.30601 | H12: 0.061 | I12: 0.0882 | J12: -0.00245096 | K12: 0.0139 | L12: 0.0696 | M12: -0.0344761 | N12: 0.0471 | O12: 23.1 | P12: 20.45 | Q12: 2.65 | R12: 17 | S12: 11.434 | T12: 14.5173 | U12: 13 | V12: =IF(A12="OAK","LV",A12) -> KC | W12: 0 | X12: 2025
A13: CIN | B13: 2024 | C13: 1617.08 | D13: 38.3564 | E13: 3.92137 | F13: 0 | G13: 1.7206 | H13: 0.1173 | I13: 0.1525 | J13: -0.0249703 | K13: 0.0725 | L13: 0.041 | M13: 0.0157217 | N13: 0.0448 | O13: 27.7647 | P13: 25.5294 | Q13: 2.2353 | R13: 9 | S13: 9.3427 | T13: 8.85417 | U13: 8 | V13: =IF(A13="OAK","LV",A13) -> CIN | W13: 0 | X13: 2025
... A65: MIA | B65: 2025 | C65: 1454.49 | D65: -4.4272 | E65: -1.46983 | F65: -1.23306 | G65: -1.23306 | H65: -0.1894 | I65: -0.5045 | J65: 0.33932 | K65: 0.3053 | L65: 0.4482 | M65: 0.138052 | N65: -0.4946 | O65: 8 | P65: 33 | Q65: -25 | R65: 0 | S65: 0.0336 | T65: 1.13016 | U65: 0 | V65: =IF(A65="OAK","LV",A65) -> MIA | W65: 1 | X65: 2025
A66: BAL | B66: 2025 | C66: 1686.87 | D66: 12.4181 | E66: 7.86033 | F66: 0.44977 | G66: 1.38142 | H66: 0.31 | I66: 0.3779 | J66: 0.147785 | K66: 0.0047 | L66: -0.0936 | M66: 0.120225 | N66: 0.3053 | O66: 40.5 | P66: 29 | Q66: 11.5 | R66: 1 | S66: 1.3763 | T66: 1.88097 | U66: 1 | V66: =IF(A66<>"",IF(A66="OAK","LV",A66),"") -> BAL | W66: =W34+1 -> 2 | X66: 2025
A67: IND | B67: 2025 | C67: 1490.73 | D67: 16.342 | E67: 0.014917 | F67: 0.571499 | G67: 3.08736 | H67: 0.2546 | I67: 0.3802 | J67: 0.0642644 | K67: 0.0353 | L67: -0.1258 | M67: 0.169023 | N67: 0.2193 | O67: 31 | P67: 18 | Q67: 13 | R67: 2 | S67: 1.5677 | T67: 1.60998 | U67: 1 | V67: =IF(A67<>"",IF(A67="OAK","LV",A67),"") -> IND | W67: =W35+1 -> 2 | X67: 2025
A68: GB | B68: 2025 | C68: 1605.54 | D68: 1.9294 | E68: 4.60737 | F68: 0.534072 | G68: 2.43722 | H68: 0.1367 | I68: 0.3156 | J68: -0.0214233 | K68: -0.0805 | L68: -0.0961 | M68: -0.194533 | N68: 0.2171 | O68: 27 | P68: 15.5 | Q68: 11.5 | R68: 2 | S68: 1.5768 | T68: 1.88908 | U68: 1 | V68: =IF(A68<>"",IF(A68="OAK","LV",A68),"") -> GB | W68: =W36+1 -> 2 | X68: 2025
A69: ATL | B69: 2025 | C69: 1485.72 | D69: -9.1881 | E69: -0.185391 | F69: 0.296235 | G69: 0.893931 | H69: 0.0147 | I69: 0.002 | J69: 0.00533364 | K69: -0.1799 | L69: -0.2302 | M69: -0.0532805 | N69: 0.1946 | O69: 21 | P69: 14.5 | Q69: 6.5 | R69: 1 | S69: 1.4127 | T69: 1.29522 | U69: 1 | V69: =IF(A69<>"",IF(A69="OAK","LV",A69),"") -> ATL | W69: =W37+1 -> 2 | X69: 2025
A70: LAR | B70: 2025 | C70: 1564.46 | D70: 3.0912 | E70: 2.96383 | F70: 1.08712 | G70: 1.85837 | H70: 0.0871 | I70: 0.1898 | J70: 0.00316698 | K70: -0.094 | L70: -0.2555 | M70: -0.00248344 | N70: 0.1811 | O70: 23.5 | P70: 14 | Q70: 9.5 | R70: 2 | S70: 1.5468 | T70: 1.58849 | U70: 1 | V70: =IF(A70<>"",IF(A70="OAK","LV",A70),"") -> LAR | W70: =W38+1 -> 2 | X70: 2025
A71: OAK | B71: 2025 | C71: 1434.77 | D71: -0.929 | E71: -2.22367 | F71: -0.94144 | G71: 0.213784 | H71: 0.1054 | I71: 0.4396 | J71: -0.306992 | K71: -0.0662 | L71: -0.0071 | M71: -0.231529 | N71: 0.1716 | O71: 29 | P71: 33 | Q71: -4 | R71: 1 | S71: 0.8481 | T71: 1.02247 | U71: 1 | V71: =IF(A71<>"",IF(A71="OAK","LV",A71),"") -> LV | W71: =W39+1 -> 2 | X71: 2025
A72: DET | B72: 2025 | C72: 1619.92 | D72: 11.6646 | E72: 5.18249 | F72: 1.19722 | G72: 0.509092 | H72: 0.154 | I72: 0.3803 | J72: -0.109868 | K72: 0.005 | L72: 0.1817 | M72: -0.249484 | N72: 0.149 | O72: 32.5 | P72: 24 | Q72: 8.5 | R72: 1 | S72: 1.3446 | T72: 1.68279 | U72: 0 | V72: =IF(A72<>"",IF(A72="OAK","LV",A72),"") -> DET | W72: =W40+1 -> 2 | X72: 2025
A73: SF | B73: 2025 | C73: 1493.49 | D73: -52.618 | E73: 0.125342 | F73: 0.600723 | G73: -0.639502 | H73: 0.0244 | I73: 0.2165 | J73: -0.143833 | K73: -0.1064 | L73: -0.3089 | M73: -0.0123585 | N73: 0.1308 | O73: 21.5 | P73: 17 | Q73: 4.5 | R73: 2 | S73: 1.2713 | T73: 1.58584 | U73: 0 | V73: =IF(A73<>"",IF(A73="OAK","LV",A73),"") -> SF | W73: =W41+1 -> 2 | X73: 2025
A74: JAX | B74: 2025 | C74: 1471.77 | D74: -0.4173 | E74: -0.743623 | F74: 0.327266 | G74: 1.20412 | H74: 0.1043 | I74: 0.0853 | J74: 0.136989 | K74: -0.0112 | L74: -0.2154 | M74: 0.0329128 | N74: 0.1154 | O74: 26.5 | P74: 20.5 | Q74: 6 | R74: 1 | S74: 1.2952 | T74: 1.34824 | U74: 1 | V74: =IF(A74<>"",IF(A74="OAK","LV",A74),"") -> JAX | W74: =W42+1 -> 2 | X74: 2025
A75: BUF | B75: 2025 | C75: 1635.64 | D75: 12.6341 | E75: 5.81111 | F75: 0.242115 | G75: 1.4075 | H75: 0.2471 | I75: 0.1909 | J75: 0.158284 | K75: 0.137 | L75: 0.1139 | M75: 0.0146766 | N75: 0.1101 | O75: 35.5 | P75: 25 | Q75: 10.5 | R75: 2 | S75: 1.3932 | T75: 2.06971 | U75: 0 | V75: =IF(A75<>"",IF(A75="OAK","LV",A75),"") -> BUF | W75: =W43+1 -> 2 | X75: 2025
A76: ARI | B76: 2025 | C76: 1503.15 | D76: 0.5137 | E76: 0.511636 | F76: -0.759873 | G76: 0.321182 | H76: 0.0381 | I76: 0.1418 | J76: 0.0203618 | K76: -0.0624 | L76: -0.007 | M76: -0.0896799 | N76: 0.1005 | O76: 23.5 | P76: 17.5 | Q76: 6 | R76: 2 | S76: 1.3358 | T76: 1.68302 | U76: 1 | V76: =IF(A76<>"",IF(A76="OAK","LV",A76),"") -> ARI | W76: =W44+1 -> 2 | X76: 2025
A77: LAC | B77: 2025 | C77: 1559.46 | D77: 11.368 | E77: 2.76385 | F77: 0.645371 | G77: 1.99715 | H77: 0.2758 | I77: 0.5167 | J77: -0.00925587 | K77: 0.1757 | L77: 0.0862 | M77: 0.523908 | N77: 0.1 | O77: 47 | P77: 30 | Q77: 17 | R77: 2 | S77: 1.4869 | T77: 1.563 | U77: 1 | V77: =IF(A77<>"",IF(A77="OAK","LV",A77),"") -> LAC | W77: =W45+1 -> 2 | X77: 2025
... A481: TEN | B481: 2025 | C481: 1311.66 | D481: -11.7022 | E481: -7.77547 | F481: 0.514663 | G481: -3.03185 | H481: -0.1775 | I481: -0.2673 | J481: -0.0977037 | K481: 0.0633 | L481: 0.1533 | M481: -0.0247067 | N481: -0.2408 | O481: 15.4615 | P481: 27.4615 | Q481: -12 | R481: 2 | S481: 2.6522 | T481: 3.43429 | U481: 1 | V481: =IF(A481<>"",IF(A481="OAK","LV",A481),"") -> TEN | W481: =W449+1 -> 14 | X481: 2025
A482: LAR | B482: 2025 | C482: 1701.78 | D482: 24.1721 | E482: 7.68803 | F482: 0.325205 | G482: 6.62389 | H482: 0.134 | I482: 0.2165 | J482: 0.0104725 | K482: -0.075 | L482: -0.0926 | M482: -0.0789134 | N482: 0.209 | O482: 30 | P482: 18.6429 | Q482: 11.3571 | R482: 11 | S482: 10.5753 | T482: 9.56405 | U482: 14 | V482: =IF(A482<>"",IF(A482="OAK","LV",A482),"") -> LAR | W482: 15 | X482: 2025
A483: SEA | B483: 2025 | C483: 1674.24 | D483: -1.3273 | E483: 6.58639 | F483: -0.366416 | G483: 6.65315 | H483: 0.0754 | I483: 0.1691 | J483: -0.107926 | K483: -0.1539 | L483: -0.1116 | M483: -0.145323 | N483: 0.2293 | O483: 28.9286 | P483: 17.2857 | Q483: 11.6429 | R483: 11 | S483: 10.8099 | T483: 9.41435 | U483: 13 | V483: =IF(A483<>"",IF(A483="OAK","LV",A483),"") -> SEA | W483: 15 | X483: 2025
A484: DET | B484: 2025 | C484: 1630.48 | D484: 8.2563 | E484: 4.83599 | F484: -0.0931888 | G484: 0.311504 | H484: 0.1269 | I484: 0.1988 | J484: 0.00369666 | K484: 0.0237 | L484: 0.0191 | M484: -0.0685829 | N484: 0.1032 | O484: 30.5714 | P484: 24.6429 | Q484: 5.9286 | R484: 8 | S484: 8.7503 | T484: 9.39623 | U484: 8 | V484: =IF(A484<>"",IF(A484="OAK","LV",A484),"") -> DET | W484: 15 | X484: 2025
