Workbook

Sheet Index
A1: BUF | B1: BUF | D1: SF | E1: SF | F1: Dallas Cowboys | G1: DAL
A2: MIA | B2: MIA | D2: KC | E2: KC | F2: Philadelphia Eagles | G2: PHI
A3: SF | B3: SF | D3: BUF | E3: BUF | F3: New York Jets | G3: NYJ
A4: CLE | B4: CLE | D4: MIA | E4: MIA | F4: Jacksonville Jaguars | G4: JAX
A5: PHI | B5: PHI | D5: DAL | E5: DAL | F5: Kansas City Chiefs | G5: KC
A6: KC | B6: KC | D6: PHI | E6: PHI | F6: New York Giants | G6: NYG
A7: DAL | B7: DAL | D7: CLE | E7: CLE | F7: New England Patriots | G7: NE
A8: BAL | B8: BAL | D8: BAL | E8: BAL | F8: Green Bay Packers | G8: GB
A9: DET | B9: DET | D9: DET | E9: DET | F9: Detroit Lions | G9: DET
A10: ARI | B10: ARI | D10: CIN | E10: CIN | F10: Washington Commanders | G10: WAS
A11: NO | B11: NO | D11: LAC | E11: LAC | F11: San Francisco 49ers | G11: SF
A12: GB | B12: GB | D12: SEA | E12: SEA | F12: Arizona Cardinals | G12: ARI
... A32: CHI | B32: CHI | D32: HOU | E32: HOU | F32: Atlanta Falcons | G32: ATL
A33: STL | B33: LAR
A34: SD | B34: LAC
A35: OAK | B35: LV
A36: JAX | B36: JAX
A37: LAR | B37: LAR

Sheet DVOA
A1: WEEK | B1: SEASON | C1: TEAM | D1: Dec Bin | E1: DVOA Adj | F1: TEAM | G1: TOTAL DVOA RANK | H1: TOTAL DVOA | I1: LAST WEEK | J1: NON-ADJ TOTAL VOA | K1: W-L | L1: OFFENSE DVOA | M1: OFFENSE RANK | N1: DEFENSE DVOA | O1: DEFENSE RANK | P1: SPECIAL TEAMS DVOA | Q1: SPECIAL TEAMS RANK | R1: OFFENSE VOA UNADJ | S1: DEFENSE VOA UNADJ | T1: SPECIAL VOA UNADJ | U1: ESTIMATED WINS | V1: RANK | W1: WEIGHTED DVOA | X1: WEIGHT RANK | Y1: PAST SCHEDULE | Z1: PAST RANK | AA1: FUTURE SCHEDULE | AB1: FUTURE RANK | AC1: VARIANCE | AD1: VAR RANK
A2: 1 | B2: 2010 | C2: =INDEX(Index!$B$1:$B$500,MATCH($F2,Index!$A$1:$A$500,0) ) -> TEN | D2: 0 | E2: =IF(D2=1,H2/100,H2) -> 0.70511004 | F2: TEN | G2: 1 | H2: 0.70511004 | K2: 1-0 | L2: 0.22943172 | M2: 6 | N2: -0.37821506 | O2: 4 | P2: 0.097463257 | Q2: 6
A3: 1 | B3: 2010 | C3: =INDEX(Index!$B$1:$B$500,MATCH($F3,Index!$A$1:$A$500,0) ) -> NE | D3: 0 | E3: =IF(D3=1,H3/100,H3) -> 0.6531498 | F3: NE | G3: 2 | H3: 0.6531498 | K3: 1-0 | L3: 0.54266093 | M3: 2 | N3: 0.07473033 | O3: 20 | P3: 0.1852192 | Q3: 2
A4: 1 | B4: 2010 | C4: =INDEX(Index!$B$1:$B$500,MATCH($F4,Index!$A$1:$A$500,0) ) -> SEA | D4: 0 | E4: =IF(D4=1,H4/100,H4) -> 0.59850683 | F4: SEA | G4: 3 | H4: 0.59850683 | K4: 1-0 | L4: 0.035383067 | M4: 13 | N4: -0.46614368 | O4: 1 | P4: 0.096980075 | Q4: 7
A5: 1 | B5: 2010 | C5: =INDEX(Index!$B$1:$B$500,MATCH($F5,Index!$A$1:$A$500,0) ) -> HOU | D5: 0 | E5: =IF(D5=1,H5/100,H5) -> 0.57392718 | F5: HOU | G5: 4 | H5: 0.57392718 | K5: 1-0 | L5: 0.56508865 | M5: 1 | N5: 0.13078022 | O5: 24 | P5: 0.13961875 | Q5: 5
A6: 1 | B6: 2010 | C6: =INDEX(Index!$B$1:$B$500,MATCH($F6,Index!$A$1:$A$500,0) ) -> GB | D6: 0 | E6: =IF(D6=1,H6/100,H6) -> 0.53854398 | F6: GB | G6: 5 | H6: 0.53854398 | K6: 1-0 | L6: 0.26996596 | M6: 5 | N6: -0.092123389 | O6: 9 | P6: 0.17645464 | Q6: 3
A7: 1 | B7: 2010 | C7: =INDEX(Index!$B$1:$B$500,MATCH($F7,Index!$A$1:$A$500,0) ) -> JAX | D7: 0 | E7: =IF(D7=1,H7/100,H7) -> 0.39799793 | F7: JAC | G7: 6 | H7: 0.39799793 | K7: 1-0 | L7: 0.38405927 | M7: 3 | N7: 0.15406465 | O7: 25 | P7: 0.16800331 | Q7: 4
A8: 1 | B8: 2010 | C8: =INDEX(Index!$B$1:$B$500,MATCH($F8,Index!$A$1:$A$500,0) ) -> MIA | D8: 0 | E8: =IF(D8=1,H8/100,H8) -> 0.38362457 | F8: MIA | G8: 7 | H8: 0.38362457 | K8: 1-0 | L8: 0.089675139 | M8: 12 | N8: -0.42574925 | O8: 3 | P8: -0.13179982 | Q8: 28
A9: 1 | B9: 2010 | C9: =INDEX(Index!$B$1:$B$500,MATCH($F9,Index!$A$1:$A$500,0) ) -> NYG | D9: 0 | E9: =IF(D9=1,H9/100,H9) -> 0.34286081 | F9: NYG | G9: 8 | H9: 0.34286081 | K9: 1-0 | L9: 0.10597059 | M9: 11 | N9: -0.45411654 | O9: 2 | P9: -0.21722633 | Q9: 30
A10: 1 | B10: 2010 | C10: =INDEX(Index!$B$1:$B$500,MATCH($F10,Index!$A$1:$A$500,0) ) -> CHI | D10: 0 | E10: =IF(D10=1,H10/100,H10) -> 0.33490914 | F10: CHI | G10: 9 | H10: 0.33490914 | K10: 1-0 | L10: -0.025280351 | M10: 20 | N10: -0.33088078 | O10: 6 | P10: 0.029308706 | Q10: 15
A11: 1 | B11: 2010 | C11: =INDEX(Index!$B$1:$B$500,MATCH($F11,Index!$A$1:$A$500,0) ) -> DAL | D11: 0 | E11: =IF(D11=1,H11/100,H11) -> 0.24329542 | F11: DAL | G11: 10 | H11: 0.24329542 | K11: 0-1 | L11: 0.32586901 | M11: 4 | N11: -0.040983887 | O11: 15 | P11: -0.12355748 | Q11: 27
A12: 1 | B12: 2010 | C12: =INDEX(Index!$B$1:$B$500,MATCH($F12,Index!$A$1:$A$500,0) ) -> NO | D12: 0 | E12: =IF(D12=1,H12/100,H12) -> 0.2008647 | F12: NO | G12: 11 | H12: 0.2008647 | K12: 1-0 | L12: 0.2150652 | M12: 7 | N12: -0.079974364 | O12: 12 | P12: -0.094174865 | Q12: 25
A13: 1 | B13: 2010 | C13: =INDEX(Index!$B$1:$B$500,MATCH($F13,Index!$A$1:$A$500,0) ) -> KC | D13: 0 | E13: =IF(D13=1,H13/100,H13) -> 0.16792251 | F13: KC | G13: 12 | H13: 0.16792251 | K13: 1-0 | L13: -0.0228242 | M13: 19 | N13: 0.092179098 | O13: 23 | P13: 0.28292581 | Q13: 1
... A7137: 18 | B7137: 2022 | C7137: =INDEX(Index!$B$1:$B$500,MATCH($F7137,Index!$A$1:$A$500,0) ) -> IND | D7137: 0 | E7137: =IF(D7137=1,H7137/100,H7137) -> -0.29332656 | F7137: IND | G7137: 32 | H7137: -0.29332656 | K7137: 4-12-1 | L7137: -0.26153509 | M7137: 32 | N7137: 0.012634713 | O7137: 17 | P7137: -0.019156751 | Q7137: 26
A7138: =#REF! -> #REF! | B7138: 2023 | C7138: =INDEX(Index!$B$1:$B$500,MATCH($F7138,Index!$A$1:$A$500,0) ) -> NYG | D7138: 0 | E7138: =IF(D7138=1,H7138/100,H7138) -> -1.0338662 | F7138: NYG | G7138: 32 | H7138: -1.0338662 | I7138: 0 | J7138: -1.0327219 | K7138: 0-1 | L7138: -0.752196 | M7138: 32 | N7138: 0.13334296 | O7138: 23 | P7138: -0.14832721 | Q7138: 32 | R7138: -0.67729962 | S7138: 0.21501676 | T7138: -0.14040552 | U7138: 0.041051709 | V7138: 31 | W7138: -1.0338662 | X7138: 32 | Y7138: 0 | Z7138: 1 | AA7138: 0.16687047 | AB7138: 1 | AC7138: 0 | AD7138: 1
A7139: =#REF! -> #REF! | B7139: 2023 | C7139: =INDEX(Index!$B$1:$B$500,MATCH($F7139,Index!$A$1:$A$500,0) ) -> CIN | D7139: 0 | E7139: =IF(D7139=1,H7139/100,H7139) -> -0.61258944 | F7139: CIN | G7139: 31 | H7139: -0.61258944 | I7139: 0 | J7139: -0.56770591 | K7139: 0-1 | L7139: -0.42929248 | M7139: 31 | N7139: 0.079686763 | O7139: 21 | P7139: -0.10361019 | Q7139: 28 | R7139: -0.42929248 | S7139: 0.049114292 | T7139: -0.08929913 | U7139: 0.22778777 | V7139: 27 | W7139: -0.61258944 | X7139: 31 | Y7139: 0 | Z7139: 1 | AA7139: -0.0032478268 | AB7139: 19 | AC7139: 0 | AD7139: 1
A7140: =#REF! -> #REF! | B7140: 2023 | C7140: =INDEX(Index!$B$1:$B$500,MATCH($F7140,Index!$A$1:$A$500,0) ) -> PIT | D7140: 0 | E7140: =IF(D7140=1,H7140/100,H7140) -> -0.51483492 | F7140: PIT | G7140: 30 | H7140: -0.51483492 | I7140: 0 | J7140: -0.56483588 | K7140: 0-1 | L7140: -0.27831613 | M7140: 28 | N7140: 0.19019799 | O7140: 26 | P7140: -0.046320802 | Q7140: 25 | R7140: -0.27831613 | S7140: 0.24742004 | T7140: -0.039099705 | U7140: 0.19847524 | V7140: 30 | W7140: -0.51483492 | X7140: 30 | Y7140: 0 | Z7140: 1 | AA7140: 0.021892097 | AB7140: 12 | AC7140: 0 | AD7140: 1
A7141: =#REF! -> #REF! | B7141: 2023 | C7141: =INDEX(Index!$B$1:$B$500,MATCH($F7141,Index!$A$1:$A$500,0) ) -> CHI | D7141: 0 | E7141: =IF(D7141=1,H7141/100,H7141) -> -0.41965556 | F7141: CHI | G7141: 29 | H7141: -0.41965556 | I7141: 0 | J7141: -0.4111414 | K7141: 0-1 | L7141: -0.18658257 | M7141: 23 | N7141: 0.21949386 | O7141: 28 | P7141: -0.013579125 | Q7141: 20 | R7141: -0.19037193 | S7141: 0.21949386 | T7141: -0.0012756046 | U7141: 0.21376409 | V7141: 28 | W7141: -0.41965556 | X7141: 29 | Y7141: 0 | Z7141: 1 | AA7141: 0.054979737 | AB7141: 3 | AC7141: 0 | AD7141: 1
A7142: =#REF! -> #REF! | B7142: 2023 | C7142: =INDEX(Index!$B$1:$B$500,MATCH($F7142,Index!$A$1:$A$500,0) ) -> IND | D7142: 0 | E7142: =IF(D7142=1,H7142/100,H7142) -> -0.3474929 | F7142: IND | G7142: 28 | H7142: -0.3474929 | I7142: 0 | J7142: -0.33636638 | K7142: 0-1 | L7142: -0.22480493 | M7142: 26 | N7142: 0.054811674 | O7142: 19 | P7142: -0.067876296 | Q7142: 27 | R7142: -0.28113463 | S7142: 0.0019573893 | T7142: -0.053274354 | U7142: 0.20384608 | V7142: 29 | W7142: -0.3474929 | X7142: 28 | Y7142: 0 | Z7142: 1 | AA7142: -0.034550954 | AB7142: 24 | AC7142: 0 | AD7142: 1
A7143: =#REF! -> #REF! | B7143: 2023 | C7143: =INDEX(Index!$B$1:$B$500,MATCH($F7143,Index!$A$1:$A$500,0) ) -> LAC | D7143: 0 | E7143: =IF(D7143=1,H7143/100,H7143) -> -0.29881255 | F7143: LAC | G7143: 27 | H7143: -0.29881255 | I7143: 0 | J7143: -0.27922067 | K7143: 0-1 | L7143: 0.40659927 | M7143: 2 | N7143: 0.7327823 | O7143: 32 | P7143: 0.027370474 | Q7143: 10 | R7143: 0.40659927 | S7143: 0.7327823 | T7143: 0.046962357 | U7143: 0.39050088 | V7143: 20 | W7143: -0.29881255 | X7143: 27 | Y7143: 0 | Z7143: 1 | AA7143: 0.043959921 | AB7143: 7 | AC7143: 0 | AD7143: 1
A7144: =#REF! -> #REF! | B7144: 2023 | C7144: =INDEX(Index!$B$1:$B$500,MATCH($F7144,Index!$A$1:$A$500,0) ) -> HOU | D7144: 0 | E7144: =IF(D7144=1,H7144/100,H7144) -> -0.28595961 | F7144: HOU | G7144: 26 | H7144: -0.28595961 | I7144: 0 | J7144: -0.31947168 | K7144: 0-1 | L7144: -0.27302682 | M7144: 27 | N7144: 0.057001838 | O7144: 20 | P7144: 0.044069045 | Q7144: 9 | R7144: -0.31364728 | S7144: 0.061624658 | T7144: 0.055800267 | U7144: 0 | V7144: 32 | W7144: -0.28595961 | X7144: 26 | Y7144: 0 | Z7144: 1 | AA7144: -0.043438576 | AB7144: 27 | AC7144: 0 | AD7144: 1
A7145: =#REF! -> #REF! | B7145: 2023 | C7145: =INDEX(Index!$B$1:$B$500,MATCH($F7145,Index!$A$1:$A$500,0) ) -> TEN | D7145: 0 | E7145: =IF(D7145=1,H7145/100,H7145) -> -0.27616478 | F7145: TEN | G7145: 25 | H7145: -0.27616478 | I7145: 0 | J7145: -0.28509827 | K7145: 0-1 | L7145: -0.31726603 | M7145: 29 | N7145: -0.033933533 | O7145: 13 | P7145: 0.0071677206 | Q7145: 15 | R7145: -0.31726603 | S7145: 0.015353322 | T7145: 0.047521081 | U7145: 0.27520083 | V7145: 25 | W7145: -0.27616478 | X7145: 25 | Y7145: 0 | Z7145: 1 | AA7145: -0.031900816 | AB7145: 23 | AC7145: 0 | AD7145: 1
A7146: =#REF! -> #REF! | B7146: 2023 | C7146: =INDEX(Index!$B$1:$B$500,MATCH($F7146,Index!$A$1:$A$500,0) ) -> SEA | D7146: 0 | E7146: =IF(D7146=1,H7146/100,H7146) -> -0.18777316 | F7146: SEA | G7146: 24 | H7146: -0.18777316 | I7146: 0 | J7146: -0.17382607 | K7146: 0-1 | L7146: 0.10813912 | M7146: 11 | N7146: 0.302258 | O7146: 30 | P7146: 0.0063457254 | Q7146: 16 | R7146: 0.10813912 | S7146: 0.302258 | T7146: 0.020292816 | U7146: 0.27587987 | V7146: 24 | W7146: -0.18777316 | X7146: 24 | Y7146: 0 | Z7146: 1 | AA7146: 0.010724371 | AB7146: 14 | AC7146: 0 | AD7146: 1
A7147: =#REF! -> #REF! | B7147: 2023 | C7147: =INDEX(Index!$B$1:$B$500,MATCH($F7147,Index!$A$1:$A$500,0) ) -> CAR | D7147: 0 | E7147: =IF(D7147=1,H7147/100,H7147) -> -0.17890568 | F7147: CAR | G7147: 23 | H7147: -0.17890568 | I7147: 0 | J7147: -0.20649735 | K7147: 0-1 | L7147: -0.21749249 | M7147: 25 | N7147: 0.035724098 | O7147: 18 | P7147: 0.074310906 | Q7147: 6 | R7147: -0.20231215 | S7147: 0.096437288 | T7147: 0.092252086 | U7147: 0.24100017 | V7147: 26 | W7147: -0.17890568 | X7147: 23 | Y7147: 0 | Z7147: 1 | AA7147: 0.071149758 | AB7147: 2 | AC7147: 0 | AD7147: 1
A7148: =#REF! -> #REF! | B7148: 2023 | C7148: =INDEX(Index!$B$1:$B$500,MATCH($F7148,Index!$A$1:$A$500,0) ) -> ARI | D7148: 0 | E7148: =IF(D7148=1,H7148/100,H7148) -> -0.16823707 | F7148: ARI | G7148: 22 | H7148: -0.16823707 | I7148: 0 | J7148: -0.20744131 | K7148: 0-1 | L7148: -0.32481609 | M7148: 30 | N7148: -0.062336963 | O7148: 12 | P7148: 0.094242055 | Q7148: 4 | R7148: -0.44988581 | S7148: -0.13372734 | T7148: 0.10871716 | U7148: 0.44179594 | V7148: 17 | W7148: -0.16823707 | X7148: 22 | Y7148: 0 | Z7148: 1 | AA7148: -0.00084679572 | AB7148: 17 | AC7148: 0 | AD7148: 1
A7149: =#REF! -> #REF! | B7149: 2023 | C7149: =INDEX(Index!$B$1:$B$500,MATCH($F7149,Index!$A$1:$A$500,0) ) -> LV | D7149: 0 | E7149: =IF(D7149=1,H7149/100,H7149) -> -0.066970919 | F7149: LV | G7149: 21 | H7149: -0.066970919 | I7149: 0 | J7149: -0.010870858 | K7149: 1-0 | L7149: 0.10523163 | M7149: 13 | N7149: 0.19499014 | O7149: 27 | P7149: 0.022787601 | Q7149: 11 | R7149: 0.13182018 | S7149: 0.19499014 | T7149: 0.052299104 | U7149: 0.51627207 | V7149: 15 | W7149: -0.066970919 | X7149: 21 | Y7149: 0 | Z7149: 1 | AA7149: -0.13639267 | AB7149: 32 | AC7149: 0 | AD7149: 1
... A7169: =#REF! -> #REF! | B7169: 2023 | C7169: =INDEX(Index!$B$1:$B$500,MATCH($F7169,Index!$A$1:$A$500,0) ) -> DAL | D7169: 0 | E7169: =IF(D7169=1,H7169/100,H7169) -> 0.79058426 | F7169: DAL | G7169: 1 | H7169: 0.79058426 | I7169: 0 | J7169: 0.86389033 | K7169: 1-0 | L7169: 0.14661962 | M7169: 9 | N7169: -0.66647494 | O7169: 1 | P7169: -0.022510303 | Q7169: 21 | R7169: 0.23320722 | S7169: -0.63959621 | T7169: -0.0089131037 | U7169: 0.74714228 | V7169: 4 | W7169: 0.79058426 | X7169: 1 | Y7169: 0 | Z7169: 1 | AA7169: -0.005515469 | AB7169: 20 | AC7169: 0 | AD7169: 1
A7170: =#REF! -> #REF! | B7170: 2023 | C7170: =INDEX(Index!$B$1:$B$500,MATCH($F7170,Index!$A$1:$A$500,0) ) -> NYG | D7170: 0 | E7170: =IF(D7170=1,H7170/100,H7170) -> -0.56813742 | F7170: NYG | G7170: 32 | H7170: -0.56813742 | I7170: 32 | J7170: -0.55915307 | K7170: 44927 | L7170: -0.29767712 | M7170: 29 | N7170: 0.20356179 | O7170: 27 | P7170: -0.066898509 | Q7170: 30 | R7170: -0.26376594 | S7170: 0.24334489 | T7170: -0.052042247 | U7170: 0.85936036 | V7170: 17 | W7170: -0.56813742 | X7170: 32 | Y7170: 0.30356329 | Z7170: 4 | AA7170: 0.13711589 | AB7170: 1 | AC7170: 0.36386574 | AD7170: 30
A7171: =#REF! -> #REF! | B7171: 2023 | C7171: =INDEX(Index!$B$1:$B$500,MATCH($F7171,Index!$A$1:$A$500,0) ) -> CHI | D7171: 0 | E7171: =IF(D7171=1,H7171/100,H7171) -> -0.47957066 | F7171: CHI | G7171: 31 | H7171: -0.47957066 | I7171: 29 | J7171: -0.44508951 | K7171: 0-2 | L7171: -0.3283262 | M7171: 30 | N7171: 0.18929529 | O7171: 26 | P7171: 0.038050827 | Q7171: 7 | R7171: -0.29226119 | S7171: 0.20793448 | T7171: 0.055106163 | U7171: 0 | V7171: 31 | W7171: -0.47957066 | X7171: 31 | Y7171: 0.25095097 | Z7171: 5 | AA7171: 0.0270221 | AB7171: 11 | AC7171: 0.0086479953 | AD7171: 8
A7172: =#REF! -> #REF! | B7172: 2023 | C7172: =INDEX(Index!$B$1:$B$500,MATCH($F7172,Index!$A$1:$A$500,0) ) -> HOU | D7172: 0 | E7172: =IF(D7172=1,H7172/100,H7172) -> -0.41652617 | F7172: HOU | G7172: 30 | H7172: -0.41652617 | I7172: 26 | J7172: -0.45899171 | K7172: 0-2 | L7172: -0.21529662 | M7172: 27 | N7172: 0.18813872 | O7172: 25 | P7172: -0.013090832 | Q7172: 19 | R7172: -0.2461505 | S7172: 0.219505 | T7172: 0.0066637873 | U7172: 0 | V7172: 31 | W7172: -0.41652617 | X7172: 30 | Y7172: 0.17855062 | Z7172: 9 | AA7172: -0.036216602 | AB7172: 24 | AC7172: 0.038860001 | AD7172: 16
A7173: =#REF! -> #REF! | B7173: 2023 | C7173: =INDEX(Index!$B$1:$B$500,MATCH($F7173,Index!$A$1:$A$500,0) ) -> CIN | D7173: 0 | E7173: =IF(D7173=1,H7173/100,H7173) -> -0.33961224 | F7173: CIN | G7173: 29 | H7173: -0.33961224 | I7173: 31 | J7173: -0.31410824 | K7173: 0-2 | L7173: -0.19256327 | M7173: 25 | N7173: 0.21478418 | O7173: 29 | P7173: 0.067735201 | Q7173: 4 | R7173: -0.19256327 | S7173: 0.20027083 | T7173: 0.078725858 | U7173: 0.23447881 | V7173: 28 | W7173: -0.33961224 | X7173: 29 | Y7173: 0.30687622 | Z7173: 3 | AA7173: 0.021818967 | AB7173: 14 | AC7173: 0.1466862 | AD7173: 27
A7174: =#REF! -> #REF! | B7174: 2023 | C7174: =INDEX(Index!$B$1:$B$500,MATCH($F7174,Index!$A$1:$A$500,0) ) -> PIT | D7174: 0 | E7174: =IF(D7174=1,H7174/100,H7174) -> -0.33854037 | F7174: PIT | G7174: 28 | H7174: -0.33854037 | I7174: 30 | J7174: -0.33830493 | K7174: 44927 | L7174: -0.42180574 | M7174: 32 | N7174: -0.058584807 | O7174: 12 | P7174: 0.02468057 | Q7174: 12 | R7174: -0.44892961 | S7174: -0.076579237 | T7174: 0.034045441 | U7174: 0.13457492 | V7174: 30 | W7174: -0.33854037 | X7174: 28 | Y7174: 0.3950837 | Z7174: 2 | AA7174: -0.038819747 | AB7174: 25 | AC7174: 0.084142541 | AD7174: 22
A7175: =#REF! -> #REF! | B7175: 2023 | C7175: =INDEX(Index!$B$1:$B$500,MATCH($F7175,Index!$A$1:$A$500,0) ) -> LV | D7175: 0 | E7175: =IF(D7175=1,H7175/100,H7175) -> -0.31981178 | F7175: LV | G7175: 27 | H7175: -0.31981178 | I7175: 21 | J7175: -0.32426477 | K7175: 44927 | L7175: -0.12602961 | M7175: 24 | N7175: 0.22250059 | O7175: 31 | P7175: 0.028718421 | Q7175: 9 | R7175: -0.1487122 | S7175: 0.22250059 | T7175: 0.046948017 | U7175: 0.6828873 | V7175: 23 | W7175: -0.31981178 | X7175: 27 | Y7175: 0.15082122 | Z7175: 10 | AA7175: -0.083332465 | AB7175: 31 | AC7175: 0.14669537 | AD7175: 28
A7176: =#REF! -> #REF! | B7176: 2023 | C7176: =INDEX(Index!$B$1:$B$500,MATCH($F7176,Index!$A$1:$A$500,0) ) -> NYJ | D7176: 0 | E7176: =IF(D7176=1,H7176/100,H7176) -> -0.23026245 | F7176: NYJ | G7176: 26 | H7176: -0.23026245 | I7176: 17 | J7176: -0.21956071 | K7176: 44927 | L7176: -0.41097826 | M7176: 31 | N7176: -0.040897821 | O7176: 13 | P7176: 0.13981799 | Q7176: 1 | R7176: -0.39998334 | S7176: -0.025966399 | T7176: 0.15445623 | U7176: 0.68661181 | V7176: 21 | W7176: -0.23026245 | X7176: 26 | Y7176: 0.51419882 | Z7176: 1 | AA7176: -0.0033236011 | AB7176: 19 | AC7176: 0.088819232 | AD7176: 23
A7177: =#REF! -> #REF! | B7177: 2023 | C7177: =INDEX(Index!$B$1:$B$500,MATCH($F7177,Index!$A$1:$A$500,0) ) -> TEN | D7177: 0 | E7177: =IF(D7177=1,H7177/100,H7177) -> -0.19976481 | F7177: TEN | G7177: 25 | H7177: -0.19976481 | I7177: 25 | J7177: -0.1906381 | K7177: 44927 | L7177: -0.19509307 | M7177: 26 | N7177: -0.011399511 | O7177: 16 | P7177: -0.016071249 | Q7177: 20 | R7177: -0.19509307 | S7177: 0.011868795 | T7177: 0.016323767 | U7177: 0.37331468 | V7177: 27 | W7177: -0.19976481 | X7177: 25 | Y7177: 0.033116328 | Z7177: 16 | AA7177: -0.013400205 | AB7177: 21 | AC7177: 0.019039671 | AD7177: 11
A7178: =#REF! -> #REF! | B7178: 2023 | C7178: =INDEX(Index!$B$1:$B$500,MATCH($F7178,Index!$A$1:$A$500,0) ) -> NE | D7178: 0 | E7178: =IF(D7178=1,H7178/100,H7178) -> -0.18212229 | F7178: NE | G7178: 24 | H7178: -0.18212229 | I7178: 14 | J7178: -0.18824356 | K7178: 0-2 | L7178: 0.014718713 | M7178: 17 | N7178: 0.17544706 | O7178: 24 | P7178: -0.021393941 | Q7178: 22 | R7178: -0.016209764 | S7178: 0.15849131 | T7178: -0.013542479 | U7178: 0.39975694 | V7178: 26 | W7178: -0.18212229 | X7178: 24 | Y7178: 0.24829072 | Z7178: 6 | AA7178: 0.022699655 | AB7178: 13 | AC7178: 0.089219824 | AD7178: 24
A7179: =#REF! -> #REF! | B7179: 2023 | C7179: =INDEX(Index!$B$1:$B$500,MATCH($F7179,Index!$A$1:$A$500,0) ) -> CAR | D7179: 0 | E7179: =IF(D7179=1,H7179/100,H7179) -> -0.16287287 | F7179: CAR | G7179: 23 | H7179: -0.16287287 | I7179: 23 | J7179: -0.17408172 | K7179: 0-2 | L7179: -0.24807655 | M7179: 28 | N7179: -0.0010741517 | O7179: 18 | P7179: 0.084129529 | Q7179: 3 | R7179: -0.25919639 | S7179: 0.020450364 | T7179: 0.10556504 | U7179: 0.22535826 | V7179: 29 | W7179: -0.16287287 | X7179: 23 | Y7179: 0.13093587 | Z7179: 11 | AA7179: 0.063418222 | AB7179: 5 | AC7179: 0.0061842722 | AD7179: 5
A7180: =#REF! -> #REF! | B7180: 2023 | C7180: =INDEX(Index!$B$1:$B$500,MATCH($F7180,Index!$A$1:$A$500,0) ) -> LAC | D7180: 0 | E7180: =IF(D7180=1,H7180/100,H7180) -> -0.13144238 | F7180: LAC | G7180: 22 | H7180: -0.13144238 | I7180: 27 | J7180: -0.10776886 | K7180: 0-2 | L7180: 0.21743052 | M7180: 3 | N7180: 0.36442751 | O7180: 32 | P7180: 0.015554608 | Q7180: 14 | R7180: 0.21743052 | S7180: 0.36442751 | T7180: 0.039228131 | U7180: 0.81233365 | V7180: 19 | W7180: -0.13144238 | X7180: 22 | Y7180: 0.070857933 | Z7180: 13 | AA7180: 0.0072947954 | AB7180: 17 | AC7180: 0.072385372 | AD7180: 21
A7181: =#REF! -> #REF! | B7181: 2023 | C7181: =INDEX(Index!$B$1:$B$500,MATCH($F7181,Index!$A$1:$A$500,0) ) -> DEN | D7181: 0 | E7181: =IF(D7181=1,H7181/100,H7181) -> -0.093646572 | F7181: DEN | G7181: 21 | H7181: -0.093646572 | I7181: 18 | J7181: -0.092428632 | K7181: 0-2 | L7181: 0.15224685 | M7181: 7 | N7181: 0.21581957 | O7181: 30 | P7181: -0.030073856 | Q7181: 23 | R7181: 0.13199089 | S7181: 0.23772578 | T7181: 0.013306257 | U7181: 0.65106393 | V7181: 25 | W7181: -0.093646572 | X7181: 21 | Y7181: -0.092602463 | Z7181: 21 | AA7181: -0.022270691 | AB7181: 22 | AC7181: 0.0026912616 | AD7181: 3
A7182: =#REF! -> #REF! | B7182: 2023 | C7182: =INDEX(Index!$B$1:$B$500,MATCH($F7182,Index!$A$1:$A$500,0) ) -> SEA | D7182: 0 | E7182: =IF(D7182=1,H7182/100,H7182) -> -0.075029264 | F7182: SEA | G7182: 20 | H7182: -0.075029264 | I7182: 24 | J7182: -0.064155309 | K7182: 44927 | L7182: 0.12216801 | M7182: 10 | N7182: 0.14618515 | O7182: 22 | P7182: -0.051012119 | Q7182: 28 | R7182: 0.12216801 | S7182: 0.15679189 | T7182: -0.02953143 | U7182: 0.84906521 | V7182: 18 | W7182: -0.075029264 | X7182: 20 | Y7182: -0.035996915 | Z7182: 18 | AA7182: 0.051256453 | AB7182: 6 | AC7182: 0.021492684 | AD7182: 12
...

Sheet DVOA Pred
A1: Season | B1: Week | C1: Home | D1: Away | E1: Home Pts | F1: Away Pts | G1: ELH | H1: ELA
A2: 2024 | B2: 2 | C2: MIA | D2: BUF | E2: 25.3 | F2: 21.2 | G2: =F2-E2 -> -4.1 | H2: =G2*-1 -> 4.1
A3: 2024 | B3: 2 | C3: BAL | D3: LV | E3: 26 | F3: 17.3 | G3: =F3-E3 -> -8.7 | H3: =G3*-1 -> 8.7
A4: 2024 | B4: 2 | C4: CAR | D4: LAC | E4: 20.4 | F4: 22.2 | G4: =F4-E4 -> 1.8 | H4: =G4*-1 -> -1.8
A5: 2024 | B5: 2 | C5: DAL | D5: NO | E5: 26.7 | F5: 20.7 | G5: =F5-E5 -> -6 | H5: =G5*-1 -> 6
A6: 2024 | B6: 2 | C6: DET | D6: TB | E6: 27.8 | F6: 20.8 | G6: =F6-E6 -> -7 | H6: =G6*-1 -> 7
A7: 2024 | B7: 2 | C7: GB | D7: IND | E7: 19.7 | F7: 23 | G7: =F7-E7 -> 3.3 | H7: =G7*-1 -> -3.3
A8: 2024 | B8: 2 | C8: JAX | D8: CLE | E8: 23.7 | F8: 21 | G8: =F8-E8 -> -2.7 | H8: =G8*-1 -> 2.7
A9: 2024 | B9: 2 | C9: MIN | D9: SF | E9: 20 | F9: 27.8 | G9: =F9-E9 -> 7.8 | H9: =G9*-1 -> -7.8
A10: 2024 | B10: 2 | C10: NE | D10: SEA | E10: 19.2 | F10: 23.7 | G10: =F10-E10 -> 4.5 | H10: =G10*-1 -> -4.5
A11: 2024 | B11: 2 | C11: TEN | D11: NYJ | E11: 19.2 | F11: 23.3 | G11: =F11-E11 -> 4.1 | H11: =G11*-1 -> -4.1
A12: 2024 | B12: 2 | C12: WAS | D12: NYG | E12: 20.7 | F12: 18.2 | G12: =F12-E12 -> -2.5 | H12: =G12*-1 -> 2.5
A13: 2024 | B13: 2 | C13: ARI | D13: LAR | E13: 22.1 | F13: 23.9 | G13: =F13-E13 -> 1.8 | H13: =G13*-1 -> -1.8
... A108: 2024 | B108: 8 | C108: PIT | D108: NYG | E108: 23.9 | F108: 16.5 | G108: =F108-E108 -> -7.4 | H108: =G108*-1 -> 7.4

Sheet WDVOA
A1: Team | B1: Year | C1: WEEK 1 | D1: WEEK 2 | E1: WEEK 3 | F1: WEEK 4 | G1: WEEK 5 | H1: WEEK 6 | I1: WEEK 7 | J1: WEEK 8 | K1: WEEK 9 | L1: WEEK 10 | M1: WEEK 11 | N1: WEEK 12 | O1: WEEK 13 | P1: WEEK 14 | Q1: WEEK 15 | R1: WEEK 16 | S1: WEEK 17 | T1: WEEK 18 | U1: Team | V1: Week | W1: Last 4
A2: ARI | B2: 2023 | C2: -0.51630592 | D2: -0.23512042 | E2: 0.72732159 | F2: -0.31749235 | G2: -0.30345467 | H2: -0.66831092 | I2: -0.55207732 | J2: -0.17572015 | K2: -1.0020736 | L2: 0.12012496 | M2: -0.041963289 | N2: -0.65594194 | O2: 0.045215837 | Q2: -0.43955183 | U2: =A2 -> ARI | V2: 15 | W2: =AVERAGE(N2:Q2) -> -0.35009264
A3: ATL | B3: 2023 | C3: -0.063610767 | D3: -0.35242022 | E3: -0.66420514 | F3: -0.26003206 | G3: 0.10526048 | H3: -0.5467368 | I3: 0.24021049 | J3: -0.3818532 | K3: -0.077245177 | L3: -0.44856672 | N3: 0.25490447 | O3: 0.12939914 | P3: -0.045306814 | Q3: -0.43255584 | U3: =A3 -> ATL | V3: 15 | W3: =AVERAGE(N3:Q3) -> -0.02338976
A4: BAL | B4: 2023 | C4: 0.30550577 | D4: 0.23715173 | E4: 0.16455011 | F4: 0.73279272 | G4: -0.15709423 | H4: 0.29663266 | I4: 1.2343398 | J4: 0.35972495 | K4: 1.0525742 | L4: -0.016279248 | M4: 0.43093479 | N4: 0.2829748 | P4: 0.48244929 | Q4: 0.29711888 | U4: =A4 -> BAL | V4: 15 | W4: =AVERAGE(N4:Q4) -> 0.35418099
A5: BUF | B5: 2023 | C5: -0.033756496 | D5: 0.58796942 | E5: 0.60817947 | F5: 1.1908499 | G5: 0.30896914 | H5: -0.22168913 | I5: -0.38782612 | J5: 0.44078477 | K5: -0.057252991 | L5: -0.10452003 | M5: 0.72128538 | N5: -0.074449842 | P5: 0.15405923 | Q5: 0.75264114 | U5: =A5 -> BUF | V5: 15 | W5: =AVERAGE(N5:Q5) -> 0.27741684
A6: CAR | B6: 2023 | C6: -0.35489873 | D6: -0.10421467 | E6: -0.48294812 | F6: -0.42040143 | G6: -0.53293462 | H6: -0.28376951 | J6: -0.13463742 | K6: -0.30674032 | L6: -0.3390613 | M6: -0.36356363 | N6: -0.42688911 | O6: -0.30244905 | P6: -0.62183444 | Q6: -0.072644644 | U6: =A6 -> CAR | V6: 15 | W6: =AVERAGE(N6:Q6) -> -0.35595431
A7: CHI | B7: 2023 | C7: -0.49448249 | D7: -0.59775653 | E7: -0.64188181 | F7: -0.069714499 | G7: 0.079039971 | H7: 0.046913667 | I7: 0.21966903 | J7: -0.4865565 | K7: -0.33117361 | L7: -0.017622117 | M7: 0.12370303 | N7: 0.19923517 | P7: 0.51701497 | Q7: -0.041933237 | U7: =A7 -> CHI | V7: 15 | W7: =AVERAGE(N7:Q7) -> 0.2247723
A8: CIN | B8: 2023 | C8: -0.5939949 | D8: 0.28137023 | E8: 0.26413546 | F8: -0.63655231 | G8: 0.050577607 | H8: 0.084370154 | J8: 0.85720066 | K8: 0.55679376 | L8: -0.43989999 | M8: -0.2027795 | N8: -0.39259147 | O8: 0.18558786 | P8: 0.3820644 | Q8: 0.15632629 | U8: =A8 -> CIN | V8: 15 | W8: =AVERAGE(N8:Q8) -> 0.082846769
A9: CLE | B9: 2023 | C9: 0.40419095 | D9: 0.16710278 | E9: 0.5452918 | F9: -0.40205441 | H9: 0.4659197 | I9: -0.21875407 | J9: -0.12943195 | K9: 0.76808454 | L9: 0.32952305 | M9: 0.0090410269 | N9: -0.6748909 | O9: -0.24709375 | P9: 0.47645981 | Q9: 0.086433313 | U9: =A9 -> CLE | V9: 15 | W9: =AVERAGE(N9:Q9) -> -0.089772883
A10: DAL | B10: 2023 | C10: 0.43617582 | D10: 0.39081389 | E10: -0.64260541 | F10: 0.44839875 | G10: -0.47355017 | H10: 0.13743522 | J10: 0.65269664 | K10: 0.26011346 | L10: 0.53477622 | M10: 0.18521207 | N10: 0.46632812 | O10: 0.0024592683 | P10: 0.54710248 | Q10: -0.36877369 | U10: =A10 -> DAL | V10: 15 | W10: =AVERAGE(N10:Q10) -> 0.16177905
A11: DEN | B11: 2023 | C11: -0.16347512 | D11: -0.41582967 | E11: -0.54095919 | F11: -0.23032361 | G11: -0.22959706 | H11: -0.31169039 | I11: 0.054030194 | J11: 0.49154718 | L11: -0.02124972 | M11: 0.13210671 | N11: 0.45114381 | O11: -0.11166629 | P11: 0.57144413 | Q11: -0.42815978 | U11: =A11 -> DEN | V11: 15 | W11: =AVERAGE(N11:Q11) -> 0.12069047
A12: DET | B12: 2023 | C12: 0.23054797 | D12: -0.08323597 | E12: 0.58138484 | F12: 0.77877122 | G12: 0.35836255 | H12: 0.38671645 | I12: -0.61326919 | J12: 0.43313678 | L12: 0.34184551 | M12: 0.13512027 | N12: -0.37770428 | O12: 0.20695089 | P12: -0.61335266 | Q12: 0.47082139 | U12: =A12 -> DET | V12: 15 | W12: =AVERAGE(N12:Q12) -> -0.078321167
A13: GB | B13: 2023 | C13: 0.33165952 | D13: 0.062185239 | E13: -0.11493356 | F13: -0.54087368 | G13: -0.18097771 | I13: -0.38711912 | J13: -0.34774053 | K13: 0.68420961 | L13: -0.18577675 | M13: -0.17274664 | N13: 0.46195478 | O13: 0.45292352 | P13: -0.57492194 | Q13: -0.34636676 | U13: =A13 -> GB | V13: 15 | W13: =AVERAGE(N13:Q13) -> -0.0016026008
A14: HOU | B14: 2023 | C14: 0.10922681 | D14: -0.56504364 | E14: 0.52639624 | F14: 0.54776232 | G14: -0.24753315 | H14: -0.11074891 | J14: -0.20675863 | K14: 0.34576482 | L14: 0.52002731 | M14: -0.23898444 | N14: 0.058440665 | O14: 0.2001417 | P14: -0.84063822 | Q14: 0.34361541 | U14: =A14 -> HOU | V14: 15 | W14: =AVERAGE(N14:Q14) -> -0.059610114
A15: IND | B15: 2023 | C15: -0.33992029 | D15: 0.5778984 | E15: 0.26132208 | F15: -0.2718744 | G15: 0.21619069 | H15: -0.28375761 | I15: 0.27571541 | J15: -0.49503217 | K15: -0.080920056 | L15: 0.015073486 | N15: 0.45617499 | O15: -0.10515018 | P15: -0.59246752 | Q15: 0.31383514 | U15: =A15 -> IND | V15: 15 | W15: =AVERAGE(N15:Q15) -> 0.018098108
A16: JAC | B16: 2023 | C16: 0.53670716 | D16: -0.19207184 | E16: -0.76422507 | F16: 0.43330957 | G16: 0.27477773 | H16: 0.413719 | I16: 0.34512943 | J16: 0.25715294 | L16: -0.40796691 | M16: 0.40105657 | N16: 0.11447211 | O16: -0.28104903 | P16: -0.077909518 | Q16: 0.002167944 | U16: =A16 -> JAC | V16: 15 | W16: =AVERAGE(N16:Q16) -> -0.060579624
A17: KC | B17: 2023 | C17: 0.017584563 | D17: 0.3679683 | E17: 0.71043727 | F17: -0.054998433 | G17: 0.35083542 | H17: 0.46802641 | I17: 0.64338824 | J17: -0.35947956 | K17: 0.43297778 | M17: -0.021582962 | N17: 0.35625191 | O17: -0.13293374 | P17: 0.42086557 | Q17: 0.14568545 | U17: =A17 -> KC | V17: 15 | W17: =AVERAGE(N17:Q17) -> 0.1974673
A18: LAC | B18: 2023 | C18: -0.12127911 | D18: -0.056615203 | E18: 0.24476508 | F18: 0.13523015 | H18: -0.059478515 | I18: -0.35809944 | J18: 0.37731983 | K18: 0.3293255 | L18: -0.12194788 | M18: -0.20194701 | N18: 0.11912783 | O18: 0.15500314 | P18: -0.53946107 | Q18: -0.85476469 | U18: =A18 -> LAC | V18: 15 | W18: =AVERAGE(N18:Q18) -> -0.2800237
A19: LA | B19: 2023 | C19: 0.09682098 | D19: 0.231245 | E19: -0.26679504 | F19: 0.061573 | G19: -0.14589911 | H19: 0.44402563 | I19: -0.33353432 | J19: -0.52295959 | K19: -0.85901918 | M19: 0.099492118 | N19: 0.26845667 | O19: 0.24324225 | P19: -0.067665881 | Q19: 0.17049766 | U19: =A19 -> LA | V19: 15 | W19: =AVERAGE(N19:Q19) -> 0.15363268
A20: LV | B20: 2023 | C20: -0.18239925 | D20: -0.44119955 | E20: -0.40306873 | F20: -0.30356094 | G20: -0.069254244 | H20: 0.12956479 | I20: -0.53647556 | J20: -0.52777447 | K20: 0.35204388 | L20: -0.09134804 | M20: -0.080869915 | N20: -0.18434223 | P20: -0.12526405 | Q20: 0.71425032 | U20: =A20 -> LV | V20: 15 | W20: =AVERAGE(N20:Q20) -> 0.13488134
A21: MIA | B21: 2023 | C21: 0.12082583 | D21: 0.30313368 | E21: 0.78968883 | F21: -0.65055774 | G21: 0.46835936 | H21: 0.23577365 | I21: -0.23762121 | J21: 0.34519541 | K21: 0.0023256053 | M21: 0.17884599 | N21: 0.48926964 | O21: 0.74547195 | P21: 0.0036259034 | Q21: 0.64134352 | U21: =A21 -> MIA | V21: 15 | W21: =AVERAGE(N21:Q21) -> 0.46992775
A22: MIN | B22: 2023 | C22: -0.10185317 | D22: 0.32638847 | E22: -0.37207754 | F22: 0.043519686 | G22: 0.031279526 | H22: 0.02465236 | I22: 0.24141846 | J22: 0.30174486 | K22: -0.10096262 | L22: 0.3750283 | M22: -0.17938421 | N22: -0.34329517 | P22: -0.078734972 | Q22: -0.035615672 | U22: =A22 -> MIN | V22: 15 | W22: =AVERAGE(N22:Q22) -> -0.1525486
A23: NE | B23: 2023 | C23: 0.08637355 | D23: -0.18034291 | E23: 0.33490214 | F23: -0.54775601 | G23: -0.99374702 | H23: -0.22867448 | I23: 0.5534108 | J23: -0.023283789 | K23: -0.33471564 | L23: -0.18106016 | N23: -0.55366032 | O23: -0.34801114 | P23: 0.27861666 | Q23: -0.16458985 | U23: =A23 -> NE | V23: 15 | W23: =AVERAGE(N23:Q23) -> -0.19691116
A24: NO | B24: 2023 | C24: 0.023541792 | D24: -0.012006291 | E24: 0.071656883 | F24: -0.48748114 | G24: 0.67459555 | H24: 0.030609198 | I24: -0.28834159 | J24: 0.3294834 | K24: 0.10963806 | L24: -0.4210757 | N24: -0.33538547 | O24: -0.2383707 | P24: 0.0026525147 | Q24: 0.49404329 | U24: =A24 -> NO | V24: 15 | W24: =AVERAGE(N24:Q24) -> -0.019265094
A25: NYG | B25: 2023 | C25: -0.89346109 | D25: -0.44814954 | E25: 0.0423855 | F25: -0.63255782 | G25: -0.65552107 | H25: -0.014231374 | I25: 0.079181091 | J25: -0.61334865 | K25: -0.74149099 | L25: -0.5015061 | M25: -0.054589778 | N25: 0.08211791 | P25: 0.11822475 | Q25: -0.81008606 | U25: =A25 -> NYG | V25: 15 | W25: =AVERAGE(N25:Q25) -> -0.2032478
A26: NYJ | B26: 2023 | C26: 0.18328205 | D26: -0.31028446 | E26: -0.5385296 | F26: 0.1579486 | G26: 0.073773797 | H26: 0.2345242 | J26: -0.01021158 | K26: -0.40751338 | L26: -0.14498656 | M26: -0.62610217 | N26: -0.5463484 | O26: -0.42271378 | P26: 0.85712605 | Q26: -0.64442617 | U26: =A26 -> NYJ | V26: 15 | W26: =AVERAGE(N26:Q26) -> -0.18909057
A27: PHI | B27: 2023 | C27: -0.046669204 | D27: 0.15955231 | E27: 0.72812059 | F27: -0.033509078 | G27: 0.40304078 | H27: -0.27537074 | I27: 0.4793292 | J27: -0.13571282 | K27: 0.025733272 | M27: 0.22188105 | N27: 0.33075046 | O27: -0.20830633 | P27: -0.19413394 | Q27: -0.071176742 | U27: =A27 -> PHI | V27: 15 | W27: =AVERAGE(N27:Q27) -> -0.035716638
A28: PIT | B28: 2023 | C28: -0.10070101 | D28: -0.099361011 | E28: 0.28749704 | F28: -0.69855757 | G28: 0.55623317 | I28: 0.32450342 | J28: 0.01484919 | K28: 0.2964627 | L28: 0.33781534 | M28: 0.07592835 | N28: 0.54533135 | O28: -0.41161821 | P28: -0.32650398 | Q28: -0.67485851 | U28: =A28 -> PIT | V28: 15 | W28: =AVERAGE(N28:Q28) -> -0.21691234
A29: SEA | B29: 2023 | C29: -0.13772288 | D29: 0.13295077 | E29: 0.034346308 | F29: 0.28946807 | H29: -0.065229021 | I29: 0.043279426 | J29: 0.27395261 | K29: -0.74023357 | L29: -0.10027171 | M29: -0.018751808 | N29: -0.051267694 | O29: 0.076330115 | P29: -0.12409607 | Q29: 0.22024917 | U29: =A29 -> SEA | V29: 15 | W29: =AVERAGE(N29:Q29) -> 0.030303881
A30: SF | B30: 2023 | C30: 0.54363929 | D30: 0.48069876 | E30: 0.19575873 | F30: 0.44847487 | G30: 0.90535212 | H30: -0.024977042 | I30: -0.090758254 | J30: -0.10575438 | L30: 0.98215705 | M30: 0.63049302 | N30: 0.52533659 | O30: 0.76226728 | P30: 0.79589939 | Q30: 0.79632854 | U30: =A30 -> SF | V30: 15 | W30: =AVERAGE(N30:Q30) -> 0.71995795
A31: TB | B31: 2023 | C31: 0.033444013 | D31: 0.40959635 | E31: -0.64343554 | F31: 0.42631935 | H31: -0.24065694 | I31: -0.56347464 | J31: -0.10924444 | K31: -0.26412552 | L31: 0.49312369 | M31: 0.028723209 | N31: -0.33239178 | O31: 0.10520282 | P31: -0.090328848 | Q31: 0.64101641 | U31: =A31 -> TB | V31: 15 | W31: =AVERAGE(N31:Q31) -> 0.08087465
A32: TEN | B32: 2023 | C32: -0.31999241 | D32: -0.17639911 | E32: -0.532302 | F32: 0.50640652 | G32: -0.13764213 | H32: 0.10612318 | J32: 0.29853133 | K32: -0.25986326 | L32: -0.65779336 | M32: -0.2773334 | N32: 0.091286652 | O32: -0.35465034 | P32: 0.10584982 | Q32: -0.46721302 | U32: =A32 -> TEN | V32: 15 | W32: =AVERAGE(N32:Q32) -> -0.15618172
A33: WAS | B33: 2023 | C33: -0.017342792 | D33: -0.05427061 | E33: -0.58328351 | F33: -0.11592104 | G33: -0.35402896 | H33: 0.23326928 | I33: -0.75727722 | J33: 0.23173772 | K33: -0.073344169 | L33: -0.10731074 | M33: -0.49162297 | N33: -0.60260158 | O33: -0.4767297 | Q33: -0.43765727 | U33: =A33 -> WAS | V33: 15 | W33: =AVERAGE(N33:Q33) -> -0.50566285
A34: ARI | B34: 2024 | C34: -0.364 | D34: 0.818 | E34: -0.216 | F34: -0.697 | G34: 0.148 | H34: -0.33 | I34: 0.16530496 | U34: =A34 -> ARI | V34: 7 | W34: =AVERAGE(E34:H34) -> -0.27375
A35: ATL | B35: 2024 | C35: -0.02 | D35: 0.164 | E35: -0.187 | F35: 0.11 | G35: 0.097 | H35: 0.305 | I35: -0.4151517 | U35: =A35 -> ATL | V35: 7 | W35: =AVERAGE(E35:H35) -> 0.08125
A36: BAL | B36: 2024 | C36: -0.133 | D36: 0.305 | E36: 0.749 | F36: 0.67 | G36: 0.148 | H36: 0.33 | I36: 0.84183626 | U36: =A36 -> BAL | V36: 7 | W36: =AVERAGE(E36:H36) -> 0.47425
A37: BUF | B37: 2024 | C37: 0.187 | D37: 0.416 | E37: 0.985 | F37: -0.501 | G37: 0.011 | H37: 0.146 | I37: 0.43128541 | U37: =A37 -> BUF | V37: 7 | W37: =AVERAGE(E37:H37) -> 0.16025
A38: CAR | B38: 2024 | C38: -0.936 | D38: -0.685 | E38: 0.441 | F38: -0.079 | G38: -0.64 | H38: -0.501 | I38: -0.90398215 | U38: =A38 -> CAR | V38: 7 | W38: =AVERAGE(E38:H38) -> -0.19475
A39: CHI | B39: 2024 | C39: -0.024 | D39: -0.411 | E39: -0.252 | F39: 0.052 | G39: 0.476 | H39: 0.409 | U39: =A39 -> CHI | V39: 7 | W39: =AVERAGE(E39:H39) -> 0.17125
A40: CIN | B40: 2024 | C40: -0.07 | D40: 0.099 | E40: 0.211 | F40: 0.071 | G40: 0.129 | H40: 0.072 | I40: 0.10244759 | U40: =A40 -> CIN | V40: 7 | W40: =AVERAGE(E40:H40) -> 0.12075
...

Sheet ALYO
A1: WEEK | B1: SEASON | C1: TEAM | D1: TEAM | E1: YEAR | F1: WEEK | G1: ADJ LINE YARDS | H1: RANK | I1: RB YARDS | J1: RANK | K1: POWER SUCCESS | L1: RANK | M1: STUFFED | N1: RANK | O1: SECOND LEVEL | P1: RANK | Q1: OPEN FIELD | R1: RANK | S1: SACKS | T1: ADJUSTED SACK RATE | U1: RANK
A2: 4 | B2: 2023 | C2: =INDEX(Index!$B$1:$B$500,MATCH($D2,Index!$A$1:$A$500,0) ) -> MIN | D2: MIN | E2: 2023 | F2: 4 | G2: 5.300138 | H2: 1 | I2: 4.6617647 | J2: 6 | K2: 0.4 | L2: 30 | M2: 0.13235294 | N2: 6 | O2: 1.75 | P2: 2 | Q2: 0.38235294 | R2: 22 | S2: 10 | T2: 0.067010015 | U2: 14
A3: 4 | B3: 2023 | C3: =INDEX(Index!$B$1:$B$500,MATCH($D3,Index!$A$1:$A$500,0) ) -> PHI | D3: PHI | E3: 2023 | F3: 4 | G3: 5.0364099 | H3: 2 | I3: 5.27 | J3: 2 | K3: 0.82352941 | L3: 6 | M3: 0.08 | N3: 1 | O3: 1.43 | P3: 4 | Q3: 0.95 | R3: 7 | S3: 11 | T3: 0.086606057 | U3: 24
A4: 4 | B4: 2023 | C4: =INDEX(Index!$B$1:$B$500,MATCH($D4,Index!$A$1:$A$500,0) ) -> BUF | D4: BUF | E4: 2023 | F4: 4 | G4: 4.9978866 | H4: 3 | I4: 4.923913 | J4: 4 | K4: 0.76923077 | L4: 9 | M4: 0.11956522 | N4: 3 | O4: 1.3913043 | P4: 6 | Q4: 0.92391304 | R4: 8 | S4: 9 | T4: 0.070446628 | U4: 16
A5: 4 | B5: 2023 | C5: =INDEX(Index!$B$1:$B$500,MATCH($D5,Index!$A$1:$A$500,0) ) -> SF | D5: SF | E5: 2023 | F5: 4 | G5: 4.9311794 | H5: 4 | I5: 5.1238095 | J5: 3 | K5: 0.75 | L5: 10 | M5: 0.11428571 | N5: 2 | O5: 1.2857143 | P5: 10 | Q5: 1.2857143 | R5: 3 | S5: 7 | T5: 0.065915929 | U5: 12
A6: 4 | B6: 2023 | C6: =INDEX(Index!$B$1:$B$500,MATCH($D6,Index!$A$1:$A$500,0) ) -> MIA | D6: MIA | E6: 2023 | F6: 4 | G6: 4.8834285 | H6: 5 | I6: 7.0434783 | J6: 1 | K6: 0.375 | L6: 31 | M6: 0.16304348 | N6: 13 | O6: 1.7634409 | P6: 1 | Q6: 2.7204301 | R6: 1 | S6: 5 | T6: 0.030868314 | U6: 2
A7: 4 | B7: 2023 | C7: =INDEX(Index!$B$1:$B$500,MATCH($D7,Index!$A$1:$A$500,0) ) -> CHI | D7: CHI | E7: 2023 | F7: 4 | G7: 4.6065226 | H7: 6 | I7: 4.6323529 | J7: 7 | K7: 0.69230769 | L7: 16 | M7: 0.13235294 | N7: 6 | O7: 1.2941176 | P7: 8 | Q7: 0.73529412 | R7: 14 | S7: 17 | T7: 0.12999734 | U7: 30
A8: 4 | B8: 2023 | C8: =INDEX(Index!$B$1:$B$500,MATCH($D8,Index!$A$1:$A$500,0) ) -> SEA | D8: SEA | E8: 2023 | F8: 4 | G8: 4.606008 | H8: 7 | I8: 4.4555556 | J8: 10 | K8: 0.58333333 | L8: 23 | M8: 0.2 | N8: 21 | O8: 1.311828 | P8: 7 | Q8: 0.79569892 | R8: 12 | S8: 7 | T8: 0.063384501 | U8: 10
A9: 4 | B9: 2023 | C9: =INDEX(Index!$B$1:$B$500,MATCH($D9,Index!$A$1:$A$500,0) ) -> DET | D9: DET | E9: 2023 | F9: 4 | G9: 4.445446 | H9: 8 | I9: 3.9916667 | J9: 18 | K9: 0.72727273 | L9: 13 | M9: 0.18333333 | N9: 16 | O9: 1.1735537 | P9: 14 | Q9: 0.43801653 | R9: 21 | S9: 5 | T9: 0.041797191 | U9: 3
A10: 4 | B10: 2023 | C10: =INDEX(Index!$B$1:$B$500,MATCH($D10,Index!$A$1:$A$500,0) ) -> DAL | D10: DAL | E10: 2023 | F10: 4 | G10: 4.4284043 | H10: 9 | I10: 3.8672566 | J10: 21 | K10: 0.66666667 | L10: 17 | M10: 0.17699115 | N10: 15 | O10: 1.0265487 | P10: 21 | Q10: 0.53097345 | R10: 18 | S10: 6 | T10: 0.049056674 | U10: 6
A11: 4 | B11: 2023 | C11: =INDEX(Index!$B$1:$B$500,MATCH($D11,Index!$A$1:$A$500,0) ) -> DEN | D11: DEN | E11: 2023 | F11: 4 | G11: 4.3773973 | H11: 10 | I11: 4.2714286 | J11: 14 | K11: 0.85714286 | L11: 2 | M11: 0.15714286 | N11: 12 | O11: 1.2857143 | P11: 10 | Q11: 0.6 | R11: 17 | S11: 11 | T11: 0.085701016 | U11: 23
A12: 4 | B12: 2023 | C12: =INDEX(Index!$B$1:$B$500,MATCH($D12,Index!$A$1:$A$500,0) ) -> NO | D12: NO | E12: 2023 | F12: 4 | G12: 4.3699701 | H12: 11 | I12: 3.3857143 | J12: 25 | K12: 0.81818182 | L12: 7 | M12: 0.14285714 | N12: 9 | O12: 0.77142857 | P12: 31 | Q12: 0.18571429 | R12: 26 | S12: 15 | T12: 0.091121212 | U12: 25
A13: 4 | B13: 2023 | C13: =INDEX(Index!$B$1:$B$500,MATCH($D13,Index!$A$1:$A$500,0) ) -> ATL | D13: ATL | E13: 2023 | F13: 4 | G13: 4.3627719 | H13: 12 | I13: 4.7857143 | J13: 5 | K13: 0.57142857 | L13: 24 | M13: 0.17346939 | N13: 14 | O13: 1.4693878 | P13: 3 | Q13: 0.96938776 | R13: 6 | S13: 16 | T13: 0.11707678 | U13: 28
... A97: 6 | B97: 2023 | C97: =INDEX(Index!$B$1:$B$500,MATCH($D97,Index!$A$1:$A$500,0) ) -> WAS | D97: WAS | E97: 2023 | F97: 6 | G97: 3.952722 | H97: 19 | I97: 4.01 | J97: 18 | K97: 0.7 | L97: 15 | M97: 0.14 | N97: 4 | O97: 1.16 | P97: 14 | Q97: 0.53 | R97: 19 | S97: 34 | T97: 0.14041821 | U97: 32
A98: =F98 -> 7 | B98: 2023 | C98: =INDEX(Index!$B$1:$B$500,MATCH($D98,Index!$A$1:$A$500,0) ) -> MIA | D98: MIA | E98: 2023 | F98: 7 | G98: 4.9250126 | H98: 1 | I98: 7.0457516 | J98: 1 | K98: 0.41666667 | L98: 32 | M98: 0.17647059 | N98: 12 | O98: 1.7857143 | P98: 1 | Q98: 2.7792208 | R98: 1 | S98: 10 | T98: 0.041663182 | U98: 2
A99: =F99 -> 7 | B99: 2023 | C99: =INDEX(Index!$B$1:$B$500,MATCH($D99,Index!$A$1:$A$500,0) ) -> MIN | D99: MIN | E99: 2023 | F99: 7 | G99: 4.7900504 | H99: 2 | I99: 4.2079208 | J99: 12 | K99: 0.7 | L99: 14 | M99: 0.14851485 | N99: 7 | O99: 1.5148515 | P99: 2 | Q99: 0.30693069 | R99: 24 | S99: 15 | T99: 0.06915792 | U99: 14
A100: =F100 -> 7 | B100: 2023 | C100: =INDEX(Index!$B$1:$B$500,MATCH($D100,Index!$A$1:$A$500,0) ) -> BUF | D100: BUF | E100: 2023 | F100: 7 | G100: 4.699501 | H100: 3 | I100: 4.4452055 | J100: 10 | K100: 0.72727273 | L100: 11 | M100: 0.1369863 | N100: 5 | O100: 1.2465753 | P100: 8 | Q100: 0.71917808 | R100: 11 | S100: 10 | T100: 0.049768067 | U100: 3
A101: =F101 -> 7 | B101: 2023 | C101: =INDEX(Index!$B$1:$B$500,MATCH($D101,Index!$A$1:$A$500,0) ) -> CHI | D101: CHI | E101: 2023 | F101: 7 | G101: 4.6860081 | H101: 4 | I101: 4.6853147 | J101: 5 | K101: 0.80952381 | L101: 4 | M101: 0.13286713 | N101: 3 | O101: 1.4405594 | P101: 4 | Q101: 0.65034965 | R101: 13 | S101: 27 | T101: 0.12021594 | U101: 30
A102: =F102 -> 7 | B102: 2023 | C102: =INDEX(Index!$B$1:$B$500,MATCH($D102,Index!$A$1:$A$500,0) ) -> SF | D102: SF | E102: 2023 | F102: 7 | G102: 4.6173285 | H102: 5 | I102: 4.721519 | J102: 3 | K102: 0.77777778 | L102: 6 | M102: 0.15822785 | N102: 10 | O102: 1.2341772 | P102: 9 | Q102: 1.0949367 | R102: 5 | S102: 11 | T102: 0.067872572 | U102: 13
A103: =F103 -> 7 | B103: 2023 | C103: =INDEX(Index!$B$1:$B$500,MATCH($D103,Index!$A$1:$A$500,0) ) -> DET | D103: DET | E103: 2023 | F103: 7 | G103: 4.5390139 | H103: 6 | I103: 4.2346369 | J103: 11 | K103: 0.64705882 | L103: 18 | M103: 0.17877095 | N103: 15 | O103: 1.1712707 | P103: 13 | Q103: 0.62983425 | R103: 17 | S103: 15 | T103: 0.057699219 | U103: 7
A104: =F104 -> 7 | B104: 2023 | C104: =INDEX(Index!$B$1:$B$500,MATCH($D104,Index!$A$1:$A$500,0) ) -> DEN | D104: DEN | E104: 2023 | F104: 7 | G104: 4.5068632 | H104: 7 | I104: 4.7086614 | J104: 4 | K104: 0.84615385 | L104: 2 | M104: 0.16535433 | N104: 11 | O104: 1.4251969 | P104: 5 | Q104: 0.94488189 | R104: 6 | S104: 20 | T104: 0.093584895 | U104: 27
A105: =F105 -> 7 | B105: 2023 | C105: =INDEX(Index!$B$1:$B$500,MATCH($D105,Index!$A$1:$A$500,0) ) -> LAR | D105: LA | E105: 2023 | F105: 7 | G105: 4.4466266 | H105: 8 | I105: 4.0903614 | J105: 16 | K105: 0.86666667 | L105: 1 | M105: 0.18674699 | N105: 18 | O105: 1.246988 | P105: 7 | Q105: 0.44578313 | R105: 21 | S105: 18 | T105: 0.074872156 | U105: 18
A106: =F106 -> 7 | B106: 2023 | C106: =INDEX(Index!$B$1:$B$500,MATCH($D106,Index!$A$1:$A$500,0) ) -> PHI | D106: PHI | E106: 2023 | F106: 7 | G106: 4.3816348 | H106: 9 | I106: 4.5031056 | J106: 8 | K106: 0.82758621 | L106: 3 | M106: 0.1242236 | N106: 1 | O106: 1.2484472 | P106: 6 | Q106: 0.72049689 | R106: 10 | S106: 17 | T106: 0.073657323 | U106: 17
A107: =F107 -> 7 | B107: 2023 | C107: =INDEX(Index!$B$1:$B$500,MATCH($D107,Index!$A$1:$A$500,0) ) -> SEA | D107: SEA | E107: 2023 | F107: 7 | G107: 4.367903 | H107: 10 | I107: 4.1824818 | J107: 13 | K107: 0.5625 | L107: 24 | M107: 0.19708029 | N107: 20 | O107: 1.1702128 | P107: 14 | Q107: 0.70921986 | R107: 12 | S107: 13 | T107: 0.07147852 | U107: 16
A108: =F108 -> 7 | B108: 2023 | C108: =INDEX(Index!$B$1:$B$500,MATCH($D108,Index!$A$1:$A$500,0) ) -> NO | D108: NO | E108: 2023 | F108: 7 | G108: 4.3130549 | H108: 11 | I108: 3.3809524 | J108: 27 | K108: 0.72727273 | L108: 11 | M108: 0.17687075 | N108: 14 | O108: 0.85714286 | P108: 29 | Q108: 0.19047619 | R108: 27 | S108: 20 | T108: 0.080351715 | U108: 23
A109: =F109 -> 7 | B109: 2023 | C109: =INDEX(Index!$B$1:$B$500,MATCH($D109,Index!$A$1:$A$500,0) ) -> BAL | D109: BAL | E109: 2023 | F109: 7 | G109: 4.2801192 | H109: 12 | I109: 4.1409396 | J109: 14 | K109: 0.77777778 | L109: 6 | M109: 0.18120805 | N109: 16 | O109: 1.1409396 | P109: 16 | Q109: 0.57718121 | R109: 19 | S109: 16 | T109: 0.077689968 | U109: 20
... A161: =F161 -> 8 | B161: 2023 | C161: =INDEX(Index!$B$1:$B$500,MATCH($D161,Index!$A$1:$A$500,0) ) -> TB | D161: TB | E161: 2023 | F161: 8 | G161: 3.2565965 | H161: 32 | I161: 2.880597 | J161: 32 | K161: 0.45454545 | L161: 30 | M161: 0.2238806 | N161: 26 | O161: 0.76119403 | P161: 32 | Q161: 0.13432836 | R161: 31 | S161: 11 | T161: 0.051837715 | U161: 4
A162: 9 | B162: 2023 | C162: =INDEX(Index!$B$1:$B$500,MATCH($D162,Index!$A$1:$A$500,0) ) -> MIA | D162: MIA | E162: 2023 | F162: 9 | G162: 4.7444477 | H162: 1 | I162: 6.5421053 | J162: 1 | K162: 0.46153846 | L162: 32 | M162: 0.17894737 | N162: 14 | O162: 1.7172775 | P162: 1 | Q162: 2.3874346 | R162: 1 | S162: 15 | T162: 0.05223334 | U162: 5
A163: 9 | B163: 2023 | C163: =INDEX(Index!$B$1:$B$500,MATCH($D163,Index!$A$1:$A$500,0) ) -> DET | D163: DET | E163: 2023 | F163: 9 | G163: 4.6850336 | H163: 2 | I163: 4.4931507 | J163: 7 | K163: 0.64705882 | L163: 16 | M163: 0.16438356 | N163: 7 | O163: 1.2850679 | P163: 5 | Q163: 0.71493213 | R163: 12 | S163: 16 | T163: 0.053124917 | U163: 6
A164: 9 | B164: 2023 | C164: =INDEX(Index!$B$1:$B$500,MATCH($D164,Index!$A$1:$A$500,0) ) -> BUF | D164: BUF | E164: 2023 | F164: 9 | G164: 4.6215308 | H164: 3 | I164: 4.3179191 | J164: 10 | K164: 0.73333333 | L164: 8 | M164: 0.13872832 | N164: 4 | O164: 1.1907514 | P164: 10 | Q164: 0.65317919 | R164: 13 | S164: 13 | T164: 0.050636797 | U164: 4
A165: 9 | B165: 2023 | C165: =INDEX(Index!$B$1:$B$500,MATCH($D165,Index!$A$1:$A$500,0) ) -> CHI | D165: CHI | E165: 2023 | F165: 9 | G165: 4.566964 | H165: 4 | I165: 4.5217391 | J165: 5 | K165: 0.73333333 | L165: 8 | M165: 0.14673913 | N165: 5 | O165: 1.3858696 | P165: 3 | Q165: 0.60869565 | R165: 15 | S165: 30 | T165: 0.10310223 | U165: 27
A166: 9 | B166: 2023 | C166: =INDEX(Index!$B$1:$B$500,MATCH($D166,Index!$A$1:$A$500,0) ) -> TEN | D166: TEN | E166: 2023 | F166: 9 | G166: 4.4851443 | H166: 5 | I166: 4.6420455 | J166: 3 | K166: 0.86666667 | L166: 1 | M166: 0.11931818 | N166: 2 | O166: 1.1777778 | P166: 12 | Q166: 0.95 | R166: 5 | S166: 29 | T166: 0.10562003 | U166: 30
A167: 9 | B167: 2023 | C167: =INDEX(Index!$B$1:$B$500,MATCH($D167,Index!$A$1:$A$500,0) ) -> BAL | D167: BAL | E167: 2023 | F167: 9 | G167: 4.4594653 | H167: 6 | I167: 4.7336683 | J167: 2 | K167: 0.81818182 | L167: 4 | M167: 0.17085427 | N167: 12 | O167: 1.2311558 | P167: 7 | Q167: 1 | R167: 3 | S167: 21 | T167: 0.073316221 | U167: 17
A168: 9 | B168: 2023 | C168: =INDEX(Index!$B$1:$B$500,MATCH($D168,Index!$A$1:$A$500,0) ) -> SF | D168: SF | E168: 2023 | F168: 9 | G168: 4.433419 | H168: 7 | I168: 4.4293194 | J168: 8 | K168: 0.76923077 | L168: 5 | M168: 0.16753927 | N168: 10 | O168: 1.140625 | P168: 16 | Q168: 0.93229167 | R168: 6 | S168: 14 | T168: 0.061862363 | U168: 8
A169: 9 | B169: 2023 | C169: =INDEX(Index!$B$1:$B$500,MATCH($D169,Index!$A$1:$A$500,0) ) -> DEN | D169: DEN | E169: 2023 | F169: 9 | G169: 4.4051884 | H169: 8 | I169: 4.5345912 | J169: 4 | K169: 0.82352941 | L169: 3 | M169: 0.18238994 | N169: 15 | O169: 1.408805 | P169: 2 | Q169: 0.80503145 | R169: 9 | S169: 26 | T169: 0.10457108 | U169: 29
A170: 9 | B170: 2023 | C170: =INDEX(Index!$B$1:$B$500,MATCH($D170,Index!$A$1:$A$500,0) ) -> WAS | D170: WAS | E170: 2023 | F170: 9 | G170: 4.2949228 | H170: 9 | I170: 4.130719 | J170: 14 | K170: 0.70588235 | L170: 12 | M170: 0.11764706 | N170: 1 | O170: 1.1568627 | P170: 15 | Q170: 0.48366013 | R170: 20 | S170: 44 | T170: 0.12713691 | U170: 31
A171: 9 | B171: 2023 | C171: =INDEX(Index!$B$1:$B$500,MATCH($D171,Index!$A$1:$A$500,0) ) -> SEA | D171: SEA | E171: 2023 | F171: 9 | G171: 4.2428665 | H171: 10 | I171: 4.392638 | J171: 9 | K171: 0.55555556 | L171: 26 | M171: 0.20858896 | N171: 23 | O171: 1.1676647 | P171: 14 | Q171: 0.95209581 | R171: 4 | S171: 18 | T171: 0.063645552 | U171: 9
A172: 9 | B172: 2023 | C172: =INDEX(Index!$B$1:$B$500,MATCH($D172,Index!$A$1:$A$500,0) ) -> LAR | D172: LA | E172: 2023 | F172: 9 | G172: 4.2415854 | H172: 11 | I172: 3.8516746 | J172: 20 | K172: 0.75 | L172: 6 | M172: 0.19617225 | N172: 18 | O172: 1.1866029 | P172: 11 | Q172: 0.35406699 | R172: 24 | S172: 21 | T172: 0.070948298 | U172: 14
A173: 9 | B173: 2023 | C173: =INDEX(Index!$B$1:$B$500,MATCH($D173,Index!$A$1:$A$500,0) ) -> NO | D173: NO | E173: 2023 | F173: 9 | G173: 4.2405234 | H173: 12 | I173: 3.3763441 | J173: 29 | K173: 0.68965517 | L173: 13 | M173: 0.19354839 | N173: 17 | O173: 0.8655914 | P173: 30 | Q173: 0.20430108 | R173: 29 | S173: 21 | T173: 0.073634791 | U173: 19
... A193: 9 | B193: 2023 | C193: =INDEX(Index!$B$1:$B$500,MATCH($D193,Index!$A$1:$A$500,0) ) -> TB | D193: TB | E193: 2023 | F193: 9 | G193: 3.3304861 | H193: 32 | I193: 2.8757764 | J193: 32 | K193: 0.58823529 | L193: 22 | M193: 0.21118012 | N193: 26 | O193: 0.76397516 | P193: 32 | Q193: 0.16149068 | R193: 32 | S193: 13 | T193: 0.05572545 | U193: 7

Sheet ALYD
A1: WEEK | B1: SEASON | C1: TEAM | D1: TEAM | E1: YEAR | F1: WEEK | G1: ADJ LINE YARDS | H1: RANK | I1: RB YARDS | J1: RANK | K1: POWER SUCCESS | L1: RANK | M1: STUFFED | N1: RANK | O1: SECOND LEVEL | P1: RANK | Q1: OPEN FIELD | R1: RANK | S1: SACKS | T1: ADJUSTED SACK RATE | U1: RANK
A2: 6 | B2: 2023 | C2: =INDEX(Index!$B$1:$B$500,MATCH($D2,Index!$A$1:$A$500,0) ) -> LAC | D2: LAC | E2: 2023 | F2: 6 | G2: 4.4900688 | H2: 24 | I2: 3.8504673 | J2: 14 | K2: 0.6 | L2: 10 | M2: 0.1588785 | N2: 24 | O2: 1.2149533 | P2: 23 | Q2: 0.3271028 | R2: 6 | S2: 21 | T2: 0.11138108 | U2: 1
A3: 6 | B3: 2023 | C3: =INDEX(Index!$B$1:$B$500,MATCH($D3,Index!$A$1:$A$500,0) ) -> BUF | D3: BUF | E3: 2023 | F3: 6 | G3: 3.7130489 | H3: 9 | I3: 5.204918 | J3: 30 | K3: 0.4 | L3: 2 | M3: 0.29508197 | N3: 1 | O3: 1.3577236 | P3: 29 | Q3: 1.9349593 | R3: 31 | S3: 24 | T3: 0.10799203 | U3: 2
A4: 6 | B4: 2023 | C4: =INDEX(Index!$B$1:$B$500,MATCH($D4,Index!$A$1:$A$500,0) ) -> CLE | D4: CLE | E4: 2023 | F4: 6 | G4: 3.0221351 | H4: 2 | I4: 3.8275862 | J4: 13 | K4: 0.66666667 | L4: 18 | M4: 0.28735632 | N4: 2 | O4: 1.1954023 | P4: 21 | Q4: 0.83908046 | R4: 25 | S4: 15 | T4: 0.10174267 | U4: 3
A5: 6 | B5: 2023 | C5: =INDEX(Index!$B$1:$B$500,MATCH($D5,Index!$A$1:$A$500,0) ) -> BAL | D5: BAL | E5: 2023 | F5: 6 | G5: 3.7076037 | H5: 8 | I5: 4.232 | J5: 23 | K5: 0.58333333 | L5: 8 | M5: 0.176 | N5: 15 | O5: 0.94444444 | P5: 6 | Q5: 1.0555556 | R5: 27 | S5: 24 | T5: 0.099609334 | U5: 4
A6: 6 | B6: 2023 | C6: =INDEX(Index!$B$1:$B$500,MATCH($D6,Index!$A$1:$A$500,0) ) -> MIA | D6: MIA | E6: 2023 | F6: 6 | G6: 4.2202158 | H6: 21 | I6: 4.1956522 | J6: 20 | K6: 0.82608696 | L6: 29 | M6: 0.15942029 | N6: 23 | O6: 1.0362319 | P6: 12 | Q6: 0.65217391 | R6: 20 | S6: 21 | T6: 0.094880952 | U6: 5
A7: 6 | B7: 2023 | C7: =INDEX(Index!$B$1:$B$500,MATCH($D7,Index!$A$1:$A$500,0) ) -> MIN | D7: MIN | E7: 2023 | F7: 6 | G7: 4.0158317 | H7: 15 | I7: 3.6666667 | J7: 11 | K7: 0.65 | L7: 16 | M7: 0.17361111 | N7: 18 | O7: 0.94482759 | P7: 7 | Q7: 0.33103448 | R7: 8 | S7: 18 | T7: 0.091832066 | U7: 6
A8: 6 | B8: 2023 | C8: =INDEX(Index!$B$1:$B$500,MATCH($D8,Index!$A$1:$A$500,0) ) -> WAS | D8: WAS | E8: 2023 | F8: 6 | G8: 4.3518214 | H8: 22 | I8: 4.168 | J8: 19 | K8: 0.8 | L8: 27 | M8: 0.128 | N8: 29 | O8: 1.1111111 | P8: 15 | Q8: 0.51587302 | R8: 16 | S8: 19 | T8: 0.091647885 | U8: 7
A9: 6 | B9: 2023 | C9: =INDEX(Index!$B$1:$B$500,MATCH($D9,Index!$A$1:$A$500,0) ) -> PIT | D9: PIT | E9: 2023 | F9: 6 | G9: 4.4500273 | H9: 23 | I9: 4.7560976 | J9: 28 | K9: 0.42857143 | L9: 4 | M9: 0.18699187 | N9: 13 | O9: 1.2439024 | P9: 24 | Q9: 1.1626016 | R9: 28 | S9: 17 | T9: 0.090847859 | U9: 8
A10: 6 | B10: 2023 | C10: =INDEX(Index!$B$1:$B$500,MATCH($D10,Index!$A$1:$A$500,0) ) -> CIN | D10: CIN | E10: 2023 | F10: 6 | G10: 4.5064089 | H10: 25 | I10: 4.7109375 | J10: 27 | K10: 0.72727273 | L10: 21 | M10: 0.1328125 | N10: 28 | O10: 1.421875 | P10: 31 | Q10: 0.953125 | R10: 26 | S10: 19 | T10: 0.086637404 | U10: 9
A11: 6 | B11: 2023 | C11: =INDEX(Index!$B$1:$B$500,MATCH($D11,Index!$A$1:$A$500,0) ) -> CAR | D11: CAR | E11: 2023 | F11: 6 | G11: 5.2553692 | H11: 32 | I11: 5.3026316 | J11: 31 | K11: 0.58823529 | L11: 9 | M11: 0.16447368 | N11: 20 | O11: 1.5064103 | P11: 32 | Q11: 1.1794872 | R11: 29 | S11: 14 | T11: 0.086100845 | U11: 10
A12: 6 | B12: 2023 | C12: =INDEX(Index!$B$1:$B$500,MATCH($D12,Index!$A$1:$A$500,0) ) -> SEA | D12: SEA | E12: 2023 | F12: 6 | G12: 2.9965511 | H12: 1 | I12: 2.6826923 | J12: 1 | K12: 0.61538462 | L12: 12 | M12: 0.25961538 | N12: 4 | O12: 0.62857143 | P12: 1 | Q12: 0.17142857 | R12: 3 | S12: 19 | T12: 0.085100702 | U12: 11
A13: 6 | B13: 2023 | C13: =INDEX(Index!$B$1:$B$500,MATCH($D13,Index!$A$1:$A$500,0) ) -> DAL | D13: DAL | E13: 2023 | F13: 6 | G13: 3.6072115 | H13: 5 | I13: 3.5932203 | J13: 9 | K13: 0.66666667 | L13: 18 | M13: 0.25423729 | N13: 5 | O13: 1.0336134 | P13: 11 | Q13: 0.4789916 | R13: 14 | S13: 16 | T13: 0.084642757 | U13: 12
... A33: 6 | B33: 2023 | C33: =INDEX(Index!$B$1:$B$500,MATCH($D33,Index!$A$1:$A$500,0) ) -> NYG | D33: NYG | E33: 2023 | F33: 6 | G33: 4.8127203 | H33: 30 | I33: 5.1354839 | J33: 29 | K33: 0.76923077 | L33: 25 | M33: 0.14193548 | N33: 27 | O33: 1.3548387 | P33: 28 | Q33: 1.2709677 | R33: 30 | S33: 5 | T33: 0.040519247 | U33: 32
A34: =F34 -> 7 | B34: 2023 | C34: =INDEX(Index!$B$1:$B$500,MATCH($D34,Index!$A$1:$A$500,0) ) -> SEA | D34: SEA | E34: 2023 | F34: 7 | G34: 3.0353328 | H34: 1 | I34: 2.8728814 | J34: 1 | K34: 0.64285714 | L34: 15 | M34: 0.24576271 | N34: 6 | O34: 0.70588235 | P34: 1 | Q34: 0.23529412 | R34: 1 | S34: 23 | T34: 0.086764115 | U34: 9
A35: =F35 -> 7 | B35: 2023 | C35: =INDEX(Index!$B$1:$B$500,MATCH($D35,Index!$A$1:$A$500,0) ) -> CLE | D35: CLE | E35: 2023 | F35: 7 | G35: 3.0947392 | H35: 2 | I35: 3.7804878 | J35: 14 | K35: 0.625 | L35: 12 | M35: 0.28455285 | N35: 1 | O35: 1.0952381 | P35: 18 | Q35: 0.77777778 | R35: 23 | S35: 19 | T35: 0.10824505 | U35: 1
A36: =F36 -> 7 | B36: 2023 | C36: =INDEX(Index!$B$1:$B$500,MATCH($D36,Index!$A$1:$A$500,0) ) -> JAX | D36: JAC | E36: 2023 | F36: 7 | G36: 3.4657543 | H36: 3 | I36: 3.446281 | J36: 3 | K36: 0.6 | L36: 10 | M36: 0.28099174 | N36: 3 | O36: 0.94214876 | P36: 4 | Q36: 0.66115702 | R36: 21 | S36: 13 | T36: 0.054241945 | U36: 30
A37: =F37 -> 7 | B37: 2023 | C37: =INDEX(Index!$B$1:$B$500,MATCH($D37,Index!$A$1:$A$500,0) ) -> CHI | D37: CHI | E37: 2023 | F37: 7 | G37: 3.5484811 | H37: 4 | I37: 3.4748201 | J37: 4 | K37: 0.78571429 | L37: 25 | M37: 0.21582734 | N37: 10 | O37: 1.1223022 | P37: 20 | Q37: 0.38848921 | R37: 9 | S37: 10 | T37: 0.043017649 | U37: 32
A38: =F38 -> 7 | B38: 2023 | C38: =INDEX(Index!$B$1:$B$500,MATCH($D38,Index!$A$1:$A$500,0) ) -> PHI | D38: PHI | E38: 2023 | F38: 7 | G38: 3.5918506 | H38: 5 | I38: 3.3018868 | J38: 2 | K38: 0.8 | L38: 26 | M38: 0.21698113 | N38: 9 | O38: 0.96226415 | P38: 6 | Q38: 0.23584906 | R38: 2 | S38: 24 | T38: 0.085774322 | U38: 12
A39: =F39 -> 7 | B39: 2023 | C39: =INDEX(Index!$B$1:$B$500,MATCH($D39,Index!$A$1:$A$500,0) ) -> DAL | D39: DAL | E39: 2023 | F39: 7 | G39: 3.6062578 | H39: 6 | I39: 3.5932203 | J39: 8 | K39: 0.66666667 | L39: 17 | M39: 0.25423729 | N39: 4 | O39: 1.0336134 | P39: 12 | Q39: 0.4789916 | R39: 14 | S39: 16 | T39: 0.081661279 | U39: 14
A40: =F40 -> 7 | B40: 2023 | C40: =INDEX(Index!$B$1:$B$500,MATCH($D40,Index!$A$1:$A$500,0) ) -> NYJ | D40: NYJ | E40: 2023 | F40: 7 | G40: 3.6404204 | H40: 7 | I40: 3.9785714 | J40: 17 | K40: 0.63636364 | L40: 14 | M40: 0.23571429 | N40: 7 | O40: 1.1702128 | P40: 22 | Q40: 0.82978723 | R40: 24 | S40: 13 | T40: 0.07392362 | U40: 18
A41: =F41 -> 7 | B41: 2023 | C41: =INDEX(Index!$B$1:$B$500,MATCH($D41,Index!$A$1:$A$500,0) ) -> BUF | D41: BUF | E41: 2023 | F41: 7 | G41: 3.7156097 | H41: 8 | I41: 4.9295775 | J41: 29 | K41: 0.53846154 | L41: 5 | M41: 0.28169014 | N41: 2 | O41: 1.3216783 | P41: 27 | Q41: 1.6923077 | R41: 31 | S41: 25 | T41: 0.099116797 | U41: 4
A42: =F42 -> 7 | B42: 2023 | C42: =INDEX(Index!$B$1:$B$500,MATCH($D42,Index!$A$1:$A$500,0) ) -> IND | D42: IND | E42: 2023 | F42: 7 | G42: 3.8269031 | H42: 9 | I42: 3.7102273 | J42: 13 | K42: 0.62962963 | L42: 13 | M42: 0.25 | N42: 5 | O42: 0.98314607 | P42: 7 | Q42: 0.71910112 | R42: 22 | S42: 20 | T42: 0.07246206 | U42: 20
A43: =F43 -> 7 | B43: 2023 | C43: =INDEX(Index!$B$1:$B$500,MATCH($D43,Index!$A$1:$A$500,0) ) -> ATL | D43: ATL | E43: 2023 | F43: 7 | G43: 3.8459404 | H43: 10 | I43: 3.6241611 | J43: 9 | K43: 0.42857143 | L43: 3 | M43: 0.20134228 | N43: 12 | O43: 1.0805369 | P43: 15 | Q43: 0.29530201 | R43: 4 | S43: 13 | T43: 0.059399789 | U43: 28
A44: =F44 -> 7 | B44: 2023 | C44: =INDEX(Index!$B$1:$B$500,MATCH($D44,Index!$A$1:$A$500,0) ) -> NO | D44: NO | E44: 2023 | F44: 7 | G44: 3.8566185 | H44: 11 | I44: 3.5263158 | J44: 6 | K44: 0.41176471 | L44: 2 | M44: 0.21804511 | N44: 8 | O44: 1.0298507 | P44: 11 | Q44: 0.32835821 | R44: 6 | S44: 13 | T44: 0.063850535 | U44: 26
A45: =F45 -> 7 | B45: 2023 | C45: =INDEX(Index!$B$1:$B$500,MATCH($D45,Index!$A$1:$A$500,0) ) -> BAL | D45: BAL | E45: 2023 | F45: 7 | G45: 3.9320648 | H45: 12 | I45: 4.4100719 | J45: 24 | K45: 0.57142857 | L45: 6 | M45: 0.16546763 | N45: 18 | O45: 1.0357143 | P45: 13 | Q45: 1.0428571 | R45: 28 | S45: 29 | T45: 0.10177244 | U45: 3
... A97: =F97 -> 8 | B97: 2023 | C97: =INDEX(Index!$B$1:$B$500,MATCH($D97,Index!$A$1:$A$500,0) ) -> CAR | D97: CAR | E97: 2023 | F97: 8 | G97: 5.0806707 | H97: 32 | I97: 5.0169492 | J97: 31 | K97: 0.54545455 | L97: 4 | M97: 0.15819209 | N97: 22 | O97: 1.4198895 | P97: 31 | Q97: 1.0497238 | R97: 29 | S97: 16 | T97: 0.088117269 | U97: 9
A98: 9 | B98: 2023 | C98: =INDEX(Index!$B$1:$B$500,MATCH($D98,Index!$A$1:$A$500,0) ) -> CLE | D98: CLE | E98: 2023 | F98: 9 | G98: 2.9314682 | H98: 1 | I98: 4.0135135 | J98: 16 | K98: 0.63636364 | L98: 15 | M98: 0.30405405 | N98: 1 | O98: 1.1390728 | P98: 20 | Q98: 1.0463576 | R98: 30 | S98: 27 | T98: 0.11583199 | U98: 1
A99: 9 | B99: 2023 | C99: =INDEX(Index!$B$1:$B$500,MATCH($D99,Index!$A$1:$A$500,0) ) -> CHI | D99: CHI | E99: 2023 | F99: 9 | G99: 3.367807 | H99: 2 | I99: 3.2272727 | J99: 1 | K99: 0.63157895 | L99: 13 | M99: 0.23295455 | N99: 5 | O99: 0.97159091 | P99: 7 | Q99: 0.32386364 | R99: 5 | S99: 10 | T99: 0.035058176 | U99: 32
A100: 9 | B100: 2023 | C100: =INDEX(Index!$B$1:$B$500,MATCH($D100,Index!$A$1:$A$500,0) ) -> JAX | D100: JAC | E100: 2023 | F100: 9 | G100: 3.3958571 | H100: 3 | I100: 3.3759398 | J100: 3 | K100: 0.6 | L100: 10 | M100: 0.27067669 | N100: 2 | O100: 0.90977444 | P100: 3 | Q100: 0.60150376 | R100: 16 | S100: 16 | T100: 0.060868315 | U100: 27
A101: 9 | B101: 2023 | C101: =INDEX(Index!$B$1:$B$500,MATCH($D101,Index!$A$1:$A$500,0) ) -> NYJ | D101: NYJ | E101: 2023 | F101: 9 | G101: 3.5298364 | H101: 4 | I101: 3.8535354 | J101: 13 | K101: 0.71428571 | L101: 21 | M101: 0.22222222 | N101: 8 | O101: 1.08 | P101: 16 | Q101: 0.765 | R101: 22 | S101: 22 | T101: 0.086973301 | U101: 8
A102: 9 | B102: 2023 | C102: =INDEX(Index!$B$1:$B$500,MATCH($D102,Index!$A$1:$A$500,0) ) -> HOU | D102: HOU | E102: 2023 | F102: 9 | G102: 3.6329065 | H102: 5 | I102: 3.3048128 | J102: 2 | K102: 0.76923077 | L102: 27 | M102: 0.20855615 | N102: 9 | O102: 0.90374332 | P102: 2 | Q102: 0.28877005 | R102: 4 | S102: 17 | T102: 0.074030218 | U102: 20
A103: 9 | B103: 2023 | C103: =INDEX(Index!$B$1:$B$500,MATCH($D103,Index!$A$1:$A$500,0) ) -> DAL | D103: DAL | E103: 2023 | F103: 9 | G103: 3.6463746 | H103: 6 | I103: 3.5246914 | J103: 4 | K103: 0.75 | L103: 25 | M103: 0.22839506 | N103: 6 | O103: 1.0368098 | P103: 12 | Q103: 0.36196319 | R103: 8 | S103: 21 | T103: 0.078762301 | U103: 15
A104: 9 | B104: 2023 | C104: =INDEX(Index!$B$1:$B$500,MATCH($D104,Index!$A$1:$A$500,0) ) -> BUF | D104: BUF | E104: 2023 | F104: 9 | G104: 3.6711332 | H104: 7 | I104: 4.622093 | J104: 28 | K104: 0.57142857 | L104: 8 | M104: 0.25581395 | N104: 3 | O104: 1.2254335 | P104: 25 | Q104: 1.4393064 | R104: 31 | S104: 29 | T104: 0.087439656 | U104: 7
A105: 9 | B105: 2023 | C105: =INDEX(Index!$B$1:$B$500,MATCH($D105,Index!$A$1:$A$500,0) ) -> SEA | D105: SEA | E105: 2023 | F105: 9 | G105: 3.7232729 | H105: 8 | I105: 3.9438202 | J105: 15 | K105: 0.71428571 | L105: 21 | M105: 0.2247191 | N105: 7 | O105: 0.94972067 | P105: 6 | Q105: 0.81005587 | R105: 25 | S105: 27 | T105: 0.075167221 | U105: 18
A106: 9 | B106: 2023 | C106: =INDEX(Index!$B$1:$B$500,MATCH($D106,Index!$A$1:$A$500,0) ) -> BAL | D106: BAL | E106: 2023 | F106: 9 | G106: 3.7575045 | H106: 9 | I106: 4.1420455 | J106: 21 | K106: 0.55555556 | L106: 5 | M106: 0.19318182 | N106: 15 | O106: 1.0338983 | P106: 10 | Q106: 0.86440678 | R106: 27 | S106: 35 | T106: 0.10290662 | U106: 2
A107: 9 | B107: 2023 | C107: =INDEX(Index!$B$1:$B$500,MATCH($D107,Index!$A$1:$A$500,0) ) -> PHI | D107: PHI | E107: 2023 | F107: 9 | G107: 3.8388464 | H107: 10 | I107: 3.6515152 | J107: 8 | K107: 0.71428571 | L107: 21 | M107: 0.1969697 | N107: 14 | O107: 1.0378788 | P107: 13 | Q107: 0.37121212 | R107: 9 | S107: 30 | T107: 0.07888402 | U107: 14
A108: 9 | B108: 2023 | C108: =INDEX(Index!$B$1:$B$500,MATCH($D108,Index!$A$1:$A$500,0) ) -> ATL | D108: ATL | E108: 2023 | F108: 9 | G108: 3.9069535 | H108: 11 | I108: 3.7222222 | J108: 10 | K108: 0.5 | L108: 2 | M108: 0.20707071 | N108: 11 | O108: 1.1010101 | P108: 18 | Q108: 0.35353535 | R108: 7 | S108: 19 | T108: 0.063174012 | U108: 26
